<?xml version="1.0" ?>
<robot name="intention">
  <mujoco>
    <compiler balanceinertia="false" discardvisual="false"/>
  </mujoco>
  <material name="silver">
    <color rgba="0.600 0.600 0.600 1.000"/>
  </material>
  <material name="black">
    <color rgba="0.1 0.1 0.1 1.000"/>
  </material>
  <material name="red">
    <color rgba="1.0 0 0 1.000"/>
  </material>
  <material name="orange">
    <color rgba="1.0 0.41 0 1.000"/>
  </material>
  <material name="invisible">
    <color rgba="0 0 0 0"/>
  </material>
  <!--
  ##########################################################
  ###########             BODY              ################
  ##########################################################
  -->
  <link name="base_link"/>
  <link name="body">
    <inertial>
      <origin rpy="0 0 0" xyz="0 0 0"/>
      <mass value="5.423"/>
      <inertia ixx="0.1946" ixy="0" ixz="0" iyy="0.4899" iyz="0" izz="0.6228"/>
    </inertial>
    <visual>
      <origin rpy="0 0 0" xyz="0 0 0"/>
      <geometry>
        <mesh filename="${find mab_description}/meshes/hb40/body.stl" scale="0.001 0.001 0.001"/>
      </geometry>
      <material name="silver"/>
    </visual>
    <collision>
      <origin rpy="0 0 0" xyz="0 0 0" />
      <geometry>
        <box size="0.22 0.2 0.1"/>
        <material name="invisible"/>
      </geometry>
    </collision>
  </link>
  <link name="rear">
    <inertial>
      <origin rpy="0 0 0" xyz="-0.038 0.075 0"/>
      <mass value="1.337"/>
      <inertia ixx="0.09" ixy="0" ixz="0" iyy="0.0835" iyz="0" izz="0.1561"/>
    </inertial>
    <visual>
      <origin rpy="0 0 0" xyz="0 0 0"/>
      <geometry>
        <mesh filename="${find mab_description}/meshes/hb40/rear.stl" scale="0.001 0.001 0.001"/>
      </geometry>
      <material name="silver"/>
    </visual>
    <collision>
      <origin rpy="0 0 0" xyz="-0.04 0.08 0" />
      <geometry>
        <box size="0.2 0.05 0.1"/>
        <material name="invisible"/>
      </geometry>
    </collision>
  </link>
  <joint name="sp_j0" type="continuous">
    <parent link="body"/>
    <child link="rear"/>
    <origin rpy="3.14159 0 4.71" xyz="-0.141 -0.0395 0"/>
    <axis xyz="1 0 0"/>
    <limit effort="48.0" lower="-0.785" upper="0.785" velocity="3.15"/>
  </joint>
  <joint name="root" type="fixed">
    <parent link="base_link"/>
    <child link="body"/>
  </joint>
  <!--
  ##########################################################
  ###########         LEGS LINKS 0-4        ################
  ##########################################################
  -->
  <link name="fr_l0">
    <inertial>
      <origin rpy="0 0 0" xyz="0.0557 -0.016 0"/>
      <mass value="0.645"/>
      <inertia ixx="0.0052" ixy="0" ixz="0" iyy="0.0093" iyz="0" izz="0.0065"/>
    </inertial>
    <visual>
      <origin rpy="0 0 0" xyz="0 0 0"/>
      <geometry>
        <mesh filename="${find mab_description}/meshes/hb40/l0r.stl" scale="0.001 0.001 0.001"/>
      </geometry>
      <material name="silver"/>
    </visual>
  </link>
  <link name="fr_l1">
    <inertial>
      <origin rpy="0 0 0" xyz="0.031 0.016 0"/>
      <mass value="0.827"/>
      <inertia ixx="0.0330" ixy="0" ixz="0" iyy="0.0077" iyz="0" izz="0.0286"/>
    </inertial>
    <visual>
      <origin rpy="0 0 0" xyz="0 0 0"/>
      <geometry>
        <mesh filename="${find mab_description}/meshes/hb40/l1r.stl" scale="0.001 0.001 0.001"/>
      </geometry>
      <material name="orange"/>
    </visual>
    <collision>
      <origin rpy="0 1.57 0" xyz="0.0 0 0"/>
      <geometry>
        <cylinder length="0.08" radius="0.05"/>
      </geometry>
    </collision>
  </link>
  <link name="fr_l2">
    <inertial>
      <origin rpy="0 0 0" xyz="0.001 0.104 -0.003"/>
      <mass value="0.118"/>
      <inertia ixx="0.0213" ixy="0" ixz="0" iyy="0.0002" iyz="0" izz="0.0212"/>
    </inertial>
    <visual>
      <origin rpy="0 0 0" xyz="0 0 0"/>
      <geometry>
        <mesh filename="${find mab_description}/meshes/hb40/l2r.stl" scale="0.001 0.001 0.001"/>
      </geometry>
      <material name="red"/>
    </visual>
    <collision>
      <origin rpy="1.3 0 0" xyz="0 0.01 0.0055"/>
      <geometry>
        <cylinder length="0.0625" radius="0.01"/>
      </geometry>
      <material name="invisible"/>
    </collision>
    <collision>
      <origin rpy="1.67 0.0 0.05" xyz="0 -0.1 0.005"/>
      <geometry>
        <cylinder length="0.2" radius="0.015"/>
      </geometry>
      <material name="invisible"/>
    </collision>
  </link>
    <link name="fr_foot">
    <inertial>
      <origin rpy="0 0 0" xyz="0.0 0.0 0.0"/>
      <mass value="0.0"/>
      <inertia ixx="0.0" ixy="0" ixz="0" iyy="0.0" iyz="0" izz="0.0"/>
    </inertial>
    <visual>
      <origin rpy="0 0 0" xyz="0 0 0"/>
      <geometry>
        <sphere radius="0.021"/>
      </geometry>
      <material name="black"/>
    </visual>
    <collision>
      <origin rpy="0 0 0" xyz="0 0 0"/>
      <geometry>
        <sphere radius="0.02"/>
      </geometry>
    </collision>
  </link>
  <link name="fl_l0">
    <inertial>
      <origin rpy="0 0 0" xyz="0.0557 -0.016 0"/>
      <mass value="0.645"/>
      <inertia ixx="0.0052" ixy="0" ixz="0" iyy="0.0093" iyz="0" izz="0.0065"/>
    </inertial>
    <visual>
      <origin rpy="0 0 0" xyz="0 0 0"/>
      <geometry>
        <mesh filename="${find mab_description}/meshes/hb40/l0l.stl" scale="0.001 0.001 0.001"/>
      </geometry>
      <material name="silver"/>
    </visual>
  </link>
  <link name="fl_l1">
    <inertial>
      <origin rpy="0 0 0" xyz="0.031 0.016 0"/>
      <mass value="0.827"/>
      <inertia ixx="0.0330" ixy="0" ixz="0" iyy="0.0077" iyz="0" izz="0.0286"/>
    </inertial>
    <visual>
      <origin rpy="0 0 0" xyz="0 0 0"/>
      <geometry>
        <mesh filename="${find mab_description}/meshes/hb40/l1lf.stl" scale="0.001 0.001 0.001"/>
      </geometry>
      <material name="orange"/>
    </visual>
    <collision>
      <origin rpy="0 1.57 0" xyz="0.0 0 0"/>
      <geometry>
        <cylinder length="0.08" radius="0.05"/>
      </geometry>
    </collision>
  </link>
  <link name="fl_l2">
    <inertial>
      <origin rpy="0 0 0" xyz="0.001 0.104 -0.003"/>
      <mass value="0.118"/>
      <inertia ixx="0.0213" ixy="0" ixz="0" iyy="0.0002" iyz="0" izz="0.0212"/>
    </inertial>
    <visual>
      <origin rpy="0 0 0" xyz="0 0 0"/>
      <geometry>
        <mesh filename="${find mab_description}/meshes/hb40/l2l.stl" scale="0.001 0.001 0.001"/>
      </geometry>
      <material name="silver"/>
    </visual>
    <collision>
      <origin rpy="-1.3 0.0 -0.00" xyz="0 -0.01 0.0055"/>
      <geometry>
        <cylinder length="0.0625" radius="0.01"/>
      </geometry>
      <material name="invisible"/>
    </collision>
    <collision>
      <origin rpy="-1.67 0.0 -0.05" xyz="0 0.1 0.005"/>
      <geometry>
        <cylinder length="0.2" radius="0.015"/>
      </geometry>
      <material name="invisible"/>
    </collision>
  </link>
  <link name="fl_foot">
    <inertial>
      <origin rpy="0 0 0" xyz="0.0 0.0 0.0"/>
      <mass value="0.0"/>
      <inertia ixx="0.0" ixy="0" ixz="0" iyy="0.0" iyz="0" izz="0.0"/>
    </inertial>
    <visual>
      <origin rpy="0 0 0" xyz="0 0 0"/>
      <geometry>
        <sphere radius="0.021"/>
      </geometry>
      <material name="black"/>
    </visual>
    <collision>
      <origin rpy="0 0 0" xyz="0 0 0"/>
      <geometry>
        <sphere radius="0.02"/>
      </geometry>
    </collision>
  </link>
  <link name="rl_l0">
    <inertial>
      <origin rpy="0 0 0" xyz="0.0557 -0.016 0"/>
      <mass value="0.645"/>
      <inertia ixx="0.0052" ixy="0" ixz="0" iyy="0.0093" iyz="0" izz="0.0065"/>
    </inertial>
    <visual>
      <origin rpy="0 0 0" xyz="0 0 0"/>
      <geometry>
        <mesh filename="${find mab_description}/meshes/hb40/l0l.stl" scale="0.001 0.001 0.001"/>
      </geometry>
      <material name="silver"/>
    </visual>
  </link>
  <link name="rl_l1">
    <inertial>
      <origin rpy="0 0 0" xyz="0.031 0.016 0"/>
      <mass value="0.827"/>
      <inertia ixx="0.0330" ixy="0" ixz="0" iyy="0.0077" iyz="0" izz="0.0286"/>
    </inertial>
    <visual>
      <origin rpy="0 0 0" xyz="0 0 0"/>
      <geometry>
        <mesh filename="${find mab_description}/meshes/hb40/l1lf.stl" scale="0.001 0.001 0.001"/>
      </geometry>
      <material name="orange"/>
    </visual>
    <collision>
      <origin rpy="0 1.57 0" xyz="0.0 0 0"/>
      <geometry>
        <cylinder length="0.08" radius="0.05"/>
      </geometry>
    </collision>
  </link>
  <link name="rl_l2">
    <inertial>
      <origin rpy="0 0 0" xyz="0.001 0.104 -0.003"/>
      <mass value="0.118"/>
      <inertia ixx="0.0213" ixy="0" ixz="0" iyy="0.0002" iyz="0" izz="0.0212"/>
    </inertial>
    <visual>
      <origin rpy="0 0 0" xyz="0 0 0"/>
      <geometry>
        <mesh filename="${find mab_description}/meshes/hb40/l2l.stl" scale="0.001 0.001 0.001"/>
      </geometry>
      <material name="silver"/>
    </visual>
    <collision>
      <origin rpy="-1.3 0 0" xyz="0 -0.01 0.0055"/>
      <geometry>
        <cylinder length="0.0625" radius="0.01"/>
      </geometry>
      <material name="invisible"/>
    </collision>
    <collision>
      <origin rpy="-1.67 0.0 -0.05" xyz="0 0.1 0.005"/>
      <geometry>
        <cylinder length="0.2" radius="0.015"/>
        <material name="invisible"/>
      </geometry>
    </collision>
  </link>
  <link name="rl_foot">
    <inertial>
      <origin rpy="0 0 0" xyz="0.0 0.0 0.0"/>
      <mass value="0.0"/>
      <inertia ixx="0.0" ixy="0" ixz="0" iyy="0.0" iyz="0" izz="0.0"/>
    </inertial>
    <visual>
      <origin rpy="0 0 0" xyz="0 0 0"/>
      <geometry>
        <sphere radius="0.021"/>
      </geometry>
      <material name="black"/>
    </visual>
    <collision>
      <origin rpy="0 0 0" xyz="0 0 0"/>
      <geometry>
        <sphere radius="0.02"/>
      </geometry>
    </collision>
  </link>
  <link name="rr_l0">
    <inertial>
      <origin rpy="0 0 0" xyz="0.0557 -0.016 0"/>
      <mass value="0.645"/>
      <inertia ixx="0.0052" ixy="0" ixz="0" iyy="0.0093" iyz="0" izz="0.0065"/>
    </inertial>
    <visual>
      <origin rpy="0 0 0" xyz="0 0 0"/>
      <geometry>
        <mesh filename="${find mab_description}/meshes/hb40/l0r.stl" scale="0.001 0.001 0.001"/>
      </geometry>
      <material name="silver"/>
    </visual>
  </link>
  <link name="rr_l1">
    <inertial>
      <origin rpy="0 0 0" xyz="0.031 0.016 0"/>
      <mass value="0.827"/>
      <inertia ixx="0.0330" ixy="0" ixz="0" iyy="0.0077" iyz="0" izz="0.0286"/>
    </inertial>
    <visual>
      <origin rpy="0 0 0" xyz="0 0 0"/>
      <geometry>
        <mesh filename="${find mab_description}/meshes/hb40/l1r.stl" scale="0.001 0.001 0.001"/>
      </geometry>
      <material name="orange"/>
    </visual>
    <collision>
      <origin rpy="0 1.57 0" xyz="0.0 0 0"/>
      <geometry>
        <cylinder length="0.08" radius="0.05"/>
      </geometry>
    </collision>
  </link>
  <link name="rr_l2">
    <inertial>
      <origin rpy="0 0 0" xyz="0.001 0.104 -0.003"/>
      <mass value="0.118"/>
      <inertia ixx="0.0213" ixy="0" ixz="0" iyy="0.0002" iyz="0" izz="0.0212"/>
    </inertial>
    <visual>
      <origin rpy="0 0 0" xyz="0 0 0"/>
      <geometry>
        <mesh filename="${find mab_description}/meshes/hb40/l2r.stl" scale="0.001 0.001 0.001"/>
      </geometry>
      <material name="silver"/>
    </visual>
    <collision>
      <origin rpy="1.3 0.0 0" xyz="0 0.01 0.0055"/>
      <geometry>
        <cylinder length="0.0625" radius="0.01"/>
        <material name="invisible"/>
      </geometry>
    </collision>
    <collision>
      <origin rpy="1.67 0.0 0.05" xyz="0 -0.1 0.005"/>
      <geometry>
        <cylinder length="0.2" radius="0.015"/>
        <material name="invisible"/>
      </geometry>
    </collision>
  </link>
  <link name="rr_foot">
    <inertial>
      <origin rpy="0 0 0" xyz="0.0 0.0 0.0"/>
      <mass value="0.0"/>
      <inertia ixx="0.0" ixy="0" ixz="0" iyy="0.0" iyz="0" izz="0.0"/>
    </inertial>
    <visual>
      <origin rpy="0 0 0" xyz="0 0 0"/>
      <geometry>
        <sphere radius="0.021"/>
      </geometry>
      <material name="black"/>
    </visual>
    <collision>
      <origin rpy="0 0 0" xyz="0 0 0"/>
      <geometry>
        <sphere radius="0.02"/>
      </geometry>
    </collision>
  </link>
  <!--
  ##########################################################
  ###########        LEGS JOINTS 0-4        ################
  ##########################################################
  -->
  <joint armature="0.01" name="fr_j0" type="continuous">
    <parent link="body"/>
    <child link="fr_l0"/>
    <origin rpy="0 0 0" xyz="0.1375 -0.064 0"/>
    <axis xyz="1.0 0 0"/>
    <limit effort="16.0" lower="-1.57" upper="1.57" velocity="25.0"/>
  </joint>
  <joint name="fr_j1" type="continuous">
    <parent link="fr_l0"/>
    <child link="fr_l1"/>
    <origin rpy="0 0 -1.57" xyz="0.0555 -0.0125 0"/>
    <axis xyz="1.0 0 0"/>
    <limit effort="16.0" lower="-1.57" upper="1.57" velocity="25.0"/>
  </joint>
  <joint name="fr_j2" type="continuous">
    <parent link="fr_l1"/>
    <child link="fr_l2"/>
    <origin rpy="2.909 0 0" xyz="0.0584 -0.200 0"/>
    <axis xyz="1.0 0 0"/>
    <limit effort="16.0" lower="-2.53" upper="0.0" velocity="25.0"/>
  </joint>
  <joint name="fr_jFoot" type="fixed">
    <parent link="fr_l2"/>
    <child link="fr_foot"/>
    <origin rpy="0 0 0" xyz="0.0054 -0.200 0"/>
    <axis xyz="0.0 0 0"/>
  </joint>
  <joint armature="0.01" name="fl_j0" type="continuous">
    <parent link="body"/>
    <child link="fl_l0"/>
    <origin rpy="0 0 0" xyz="0.1375 0.064 0"/>
    <axis xyz="1.0 0 0"/>
    <limit effort="16.0" lower="-1.57" upper="1.57" velocity="25.0"/>
  </joint>
  <joint name="fl_j1" type="continuous">
    <parent link="fl_l0"/>
    <child link="fl_l1"/>
    <origin rpy="0 0 1.57" xyz="0.0555 0.0125 0"/>
    <axis xyz="1.0 0 0"/>
    <limit effort="16.0" lower="-1.57" upper="1.57" velocity="25.0"/>
  </joint>
  <joint name="fl_j2" type="continuous">
    <parent link="fl_l1"/>
    <child link="fl_l2"/>
    <origin rpy="-2.909 0 0" xyz="0.0584 0.200 0"/>
    <axis xyz="1.0 0 0"/>
    <limit effort="16.0" lower="0" upper="2.53" velocity="25.0"/>
  </joint> 
  <joint name="fl_jFoot" type="fixed">
    <parent link="fl_l2"/>
    <child link="fl_foot"/>
    <origin rpy="0 0 0" xyz="0.0054 0.200 0"/>
    <axis xyz="0.0 0 0"/>
  </joint>
  <joint armature="0.01" name="rl_j0" type="continuous">
    <parent link="rear"/>
    <child link="rl_l0"/>
    <origin rpy="0 0 1.57" xyz="-0.1025 0.10765 0"/>
    <axis xyz="1.0 0 0"/>
    <limit effort="16.0" lower="-1.57" upper="1.57" velocity="25.0"/>
  </joint>
  <joint name="rl_j1" type="continuous">
    <parent link="rl_l0"/>
    <child link="rl_l1"/>
    <origin rpy="3.14159 0 1.57" xyz="0.0555 0.0125 0"/>
    <axis xyz="1.0 0 0"/>
    <limit effort="16.0" lower="-1.57" upper="1.57" velocity="25.0"/>
  </joint>
  <joint name="rl_j2" type="continuous">
    <parent link="rl_l1"/>
    <child link="rl_l2"/>
    <origin rpy="-2.909 0 0" xyz="0.0584 0.20 0"/>
    <axis xyz="1.0 0 0"/>
    <limit effort="16.0" lower="0" upper="2.53" velocity="25.0"/>
  </joint>
  <joint name="rl_jFoot" type="fixed">
    <parent link="rl_l2"/>
    <child link="rl_foot"/>
    <origin rpy="0 0 0" xyz="0.0054 0.200 0"/>
    <axis xyz="0.0 0 0"/>
  </joint>
  <joint armature="0.01" name="rr_j0" type="continuous">
    <parent link="rear"/>
    <child link="rr_l0"/>
    <origin rpy="0 0 1.57" xyz="0.0255 0.10725 0"/>
    <axis xyz="1.0 0 0"/>
    <limit effort="16.0" lower="-1.57" upper="1.57" velocity="25.0"/>
  </joint>
  <joint name="rr_j1" type="continuous">
    <parent link="rr_l0"/>
    <child link="rr_l1"/>
    <origin rpy="3.14159 0 -1.57" xyz="0.0555 -0.0125 0"/>
    <axis xyz="1.0 0 0"/>
    <limit effort="16.0" lower="-1.57" upper="1.57" velocity="25.0"/>
  </joint>
  <joint name="rr_j2" type="continuous">
    <parent link="rr_l1"/>
    <child link="rr_l2"/>
    <origin rpy="2.909 0 0" xyz="0.0584 -0.20 0"/>
    <axis xyz="1.0 0 0"/>
    <limit effort="16.0" lower="-2.53" upper="0.0" velocity="25.0"/>
  </joint>
  <joint name="rr_jFoot" type="fixed">
    <parent link="rr_l2"/>
    <child link="rr_foot"/>
    <origin rpy="0 0 0" xyz="0.0054 -0.200 0"/>
    <axis xyz="0.0 0 0"/>
  </joint>
</robot>
