<?xml version="1.0"?>

<robot name="go2" xmlns:xacro="http://www.ros.org/wiki/xacro">

    <xacro:arg name="DEBUG" default="false"/>

    <xacro:include filename="$(find go2_description)/xacro/const.xacro"/>
    <xacro:include filename="$(find go2_description)/xacro/materials.xacro"/>
    <xacro:include filename="$(find go2_description)/xacro/leg.xacro"/>
    <!-- <xacro:include filename="$(find go2_description)/xacro/stairs.xacro"/> -->
    <xacro:include filename="$(find go2_description)/xacro/gazebo.xacro"/>
    <!-- <xacro:include filename="$(find go2_gazebo)/launch/stairs.urdf.xacro"/> -->

    <!-- <xacro:stairs stairs="15" xpos="0" ypos="0" zpos="0" /> -->

    <xacro:include filename="$(find go2_description)/xacro/transmission.xacro"/>

    <!-- Initialize camera-->
    <xacro:include filename="$(find go2_description)/xacro/camera.xacro"/>

    <!-- Rotor related joint and link is only for demonstrate location. -->
    <!-- Actually, the rotor will rotate and the joint is not fixed. Reduction ratio should be considered. -->

    <!-- Debug mode will hung up the robot, use "true" or "false" to switch it. -->
    <xacro:if value="$(arg DEBUG)">
        <link name="world"/>
        <joint name="base_static_joint" type="fixed">
            <origin rpy="0 0 0" xyz="0 0 0"/>
            <parent link="world"/>
            <child link="base"/>
        </joint>
    </xacro:if> 

    <link name="base">
        <visual>
            <origin rpy="0 0 0" xyz="0 0 0"/>
            <geometry>
                <box size="0.001 0.001 0.001"/>
            </geometry>
        </visual>
    </link>

    <joint name="floating_base" type="fixed">
        <origin rpy="0 0 0" xyz="0 0 0"/>
        <parent link="base"/>
        <child link="trunk"/>
    </joint>

    <link name="trunk">
        <visual>
            <origin rpy="0 0 0" xyz="0 0 0"/>
            <geometry>
                <mesh filename="package://go2_description/meshes/trunk.dae" scale="1 1 1"/>
            </geometry>
            <!-- <material name="orange"/> -->
        </visual>
        <collision>
            <origin rpy="0 0 0" xyz="0 0 0"/>
            <geometry>
                <box size="${trunk_length} ${trunk_width} ${trunk_height}"/>
            </geometry>
        </collision>
        <inertial>
            <origin rpy="0 0 0" xyz="${trunk_com_x} ${trunk_com_y} ${trunk_com_z}"/>
            <mass value="${trunk_mass}"/>
            <inertia
                ixx="${trunk_ixx}" ixy="${trunk_ixy}" ixz="${trunk_ixz}"
                iyy="${trunk_iyy}" iyz="${trunk_iyz}"
                izz="${trunk_izz}"/>  
        </inertial>
    </link>

    <xacro:realsense2_camera parent="trunk" name="d435i_camera"/>

    <joint name="imu_joint" type="fixed">
        <parent link="trunk"/>
        <child link="imu_link"/>
        <origin rpy="0 0 0" xyz="0 0 0"/>
    </joint>

    <link name="imu_link">
        <inertial>
            <mass value="0.001"/>
            <origin rpy="0 0 0" xyz="0 0 0"/>
            <inertia ixx="0.0001" ixy="0" ixz="0" iyy="0.0001" iyz="0" izz="0.0001"/>
        </inertial>
        <visual>
            <origin rpy="0 0 0" xyz="0 0 0"/>
            <geometry>
                <box size="0.001 0.001 0.001"/>
            </geometry>
            <!-- <material name="red"/> -->
        </visual>
        <collision>
            <origin rpy="0 0 0" xyz="0 0 0"/>
            <geometry>
                <box size=".001 .001 .001"/>
            </geometry>
        </collision>
    </link>
    <!--
    <joint name="load_joint" type="fixed">
        <parent link="trunk"/>
        <child link="load_link"/>
        <origin rpy="0 0 0" xyz="0 0 0"/>
    </joint>

    <link name="load_link">
        <inertial>
            <mass value="5"/>
            <origin rpy="0 0 0" xyz="0 0 0"/>
            <inertia ixx="0.01" ixy="0" ixz="0" iyy="0.01" iyz="0" izz="0.01"/>
        </inertial>
        <visual>
            <origin rpy="0 0 0" xyz="0 0 0.2"/>
            <geometry>
                <box size="0.5 0.3 0.2"/>
            </geometry>
        </visual>
        <collision>
            <origin rpy="0 0 0" xyz="0 0 0"/>
            <geometry>
                <box size=".001 .001 .001"/>
            </geometry>
        </collision>
    </link>
-->

    <!-- DON'T USE THIS, modified axes for locomotion policy -->
    <!-- <xacro:leg name="FR" mirror="-1" mirror_dae= "False" front_hind="1"  front_hind_dae="True"  />
    <xacro:leg name="FL" mirror="1"  mirror_dae="True"   front_hind="1"  front_hind_dae="True"  />
    <xacro:leg name="RR" mirror="-1" mirror_dae="False"  front_hind="-1" front_hind_dae="False" />
    <xacro:leg name="RL" mirror="1"  mirror_dae="True"   front_hind="-1" front_hind_dae="False" /> -->

    <joint name="FR_hip_joint" type="revolute">
        <origin rpy="0 0 0" xyz="0.1934 -0.0465 0"/>
        <parent link="trunk"/>
        <child link="FR_hip"/>
        <axis xyz="1 0 0"/>
        <dynamics damping="0.0" friction="0.0"/>
        <limit effort="23.7" lower="-1.0472" upper="1.0472" velocity="30.1"/>
    </joint>
    <joint name="FR_hip_rotor_joint" type="fixed">
        <origin rpy="0 0 0" xyz="0.11215 -0.04675 0"/>
        <parent link="trunk"/>
        <child link="FR_hip_rotor"/>
    </joint>
    <link name="FR_hip">
        <visual>
        <origin rpy="3.141592653589793 0 0" xyz="0 0 0"/>
        <geometry>
            <mesh filename="package://go2_description/meshes/hip.dae" scale="1 1 1"/>
        </geometry>
        <!-- <material name="orange"/> -->
        </visual>
        <collision>
        <origin rpy="1.5707963267948966 0 0" xyz="0 -0.0955 0"/>
        <geometry>
            <cylinder length="0.04" radius="0.046"/>
        </geometry>
        </collision>
        <inertial>
        <origin rpy="0 0 0" xyz="-0.0054 -0.00194 -0.000105"/>
        <mass value="0.678"/>
        <inertia ixx="0.00048" ixy="3.01e-06" ixz="1.11e-06" iyy="0.000884" iyz="1.42e-06" izz="0.000596"/>
        </inertial>
    </link>
    <link name="FR_hip_rotor">
        <visual>
        <origin rpy="0 1.5707963267948966 0" xyz="0 0 0"/>
        <geometry>
            <cylinder length="0.02" radius="0.035"/>
        </geometry>
        <material name="green"/>
        </visual>
        <!-- <collision>
                    <origin rpy="0 ${PI/2.0} 0" xyz="0 0 0"/>
                    <geometry>
                        <cylinder length="0.02" radius="0.035"/>
                    </geometry>
                </collision> -->
        <inertial>
        <origin rpy="0 0 0" xyz="0.0 0.0 0.0"/>
        <mass value="0.089"/>
        <inertia ixx="0.000111842" ixy="0.0" ixz="0.0" iyy="5.9647e-05" iyz="0.0" izz="5.9647e-05"/>
        </inertial>
    </link>
    <joint name="FR_thigh_joint" type="revolute">
        <origin rpy="0 0 0" xyz="0 -0.0955 0"/>
        <parent link="FR_hip"/>
        <child link="FR_thigh"/>
        <axis xyz="0 -1 0"/>
        <dynamics damping="0.0" friction="0.0"/>
        <limit effort="23.7" lower="-3.4907" upper="1.5708" velocity="30.1"/>
    </joint>
    <joint name="FR_thigh_rotor_joint" type="fixed">
        <origin rpy="0 0 0" xyz="0.0 0.00015 0"/>
        <parent link="FR_hip"/>
        <child link="FR_thigh_rotor"/>
    </joint>
    <link name="FR_thigh">
        <visual>
        <origin rpy="0 0 0" xyz="0 0 0"/>
        <geometry>
            <mesh filename="package://go2_description/meshes/thigh_mirror.dae" scale="1 1 1"/>
        </geometry>
        <!-- <material name="orange"/> -->
        </visual>
        <collision>
        <origin rpy="0 1.5707963267948966 0" xyz="0 0 -0.1065"/>
        <geometry>
            <box size="0.213 0.0245 0.034"/>
        </geometry>
        </collision>
        <inertial>
        <origin rpy="0 0 0" xyz="-0.00374 0.0223 -0.0327"/>
        <mass value="1.152"/>
        <inertia ixx="0.00584" ixy="-8.72e-05" ixz="-0.000289" iyy="0.0058" iyz="-0.000808" izz="0.00103"/>
        </inertial>
    </link>
    <link name="FR_thigh_rotor">
        <visual>
        <origin rpy="1.5707963267948966 0 0" xyz="0 0 0"/>
        <geometry>
            <cylinder length="0.02" radius="0.035"/>
        </geometry>
        <material name="green"/>
        </visual>
        <!-- <collision>
                    <origin rpy="${PI/2.0} 0 0" xyz="0 0 0"/>
                    <geometry>
                        <cylinder length="0.02" radius="0.035"/>
                    </geometry>
                </collision> -->
        <inertial>
        <origin rpy="0 0 0" xyz="0.0 0.0 0.0"/>
        <mass value="0.089"/>
        <inertia ixx="5.9647e-05" ixy="0.0" ixz="0.0" iyy="0.000111842" iyz="0.0" izz="5.9647e-05"/>
        </inertial>
    </link>
    <joint name="FR_calf_joint" type="revolute">
        <origin rpy="0 0 0" xyz="0 0 -0.213"/>
        <parent link="FR_thigh"/>
        <child link="FR_calf"/>
        <axis xyz="0 -1 0"/>
        <dynamics damping="0.0" friction="0.0"/>
        <limit effort="35.55" lower="0.83776" upper="2.7227" velocity="20.06"/>
    </joint>
    <joint name="FR_calf_rotor_joint" type="fixed">
        <origin rpy="0 0 0" xyz="0.0 0.03235 0"/>
        <parent link="FR_thigh"/>
        <child link="FR_calf_rotor"/>
    </joint>
    <link name="FR_calf">
        <visual>
        <origin rpy="0 0 0" xyz="0 0 0"/>
        <geometry>
            <mesh filename="package://go2_description/meshes/calf.dae" scale="1 1 1"/>
        </geometry>
        <!-- <material name="orange"/> -->
        </visual>
        <collision>
        <origin rpy="0 1.5707963267948966 0" xyz="0 0 -0.1065"/>
        <geometry>
            <box size="0.213 0.016 0.016"/>
        </geometry>
        </collision>
        <inertial>
        <origin rpy="0 0 0" xyz="0.00548 -0.000975 -0.115"/>
        <mass value="0.154"/>
        <inertia ixx="0.00108" ixy="3.4e-07" ixz="1.72e-05" iyy="0.0011" iyz="8.28e-06" izz="3.29e-05"/>
        </inertial>
    </link>
    <link name="FR_calf_rotor">
        <visual>
        <origin rpy="1.5707963267948966 0 0" xyz="0 0 0"/>
        <geometry>
            <cylinder length="0.02" radius="0.035"/>
        </geometry>
        <material name="green"/>
        </visual>
        <!-- <collision>
                    <origin rpy="${PI/2.0} 0 0" xyz="0 0 0"/>
                    <geometry>
                        <cylinder length="0.02" radius="0.035"/>
                    </geometry>
                </collision> -->
        <inertial>
        <origin rpy="0 0 0" xyz="0.0 0.0 0.0"/>
        <mass value="0.089"/>
        <inertia ixx="5.9647e-05" ixy="0.0" ixz="0.0" iyy="0.000111842" iyz="0.0" izz="5.9647e-05"/>
        </inertial>
    </link>
    <joint name="FR_foot_fixed" type="fixed">
        <origin rpy="0 0 0" xyz="0 0 -0.213"/>
        <parent link="FR_calf"/>
        <child link="FR_foot"/>
    </joint>
    <link name="FR_foot">
        <visual>
        <origin rpy="0 0 0" xyz="0 0 0"/>
        <geometry>
            <sphere radius="0.01"/>
        </geometry>
        <!-- <material name="orange"/> -->
        </visual>
        <collision>
        <origin rpy="0 0 0" xyz="0 0 0"/>
        <geometry>
            <sphere radius="0.02"/>
        </geometry>
        </collision>
        <inertial>
        <mass value="0.06"/>
        <inertia ixx="9.600000000000001e-06" ixy="0.0" ixz="0.0" iyy="9.600000000000001e-06" iyz="0.0" izz="9.600000000000001e-06"/>
        </inertial>
    </link>
    <xacro:leg_transmission name="FR"/>


    <joint name="FL_hip_joint" type="revolute">
        <origin rpy="0 0 0" xyz="0.1934 0.0465 0"/>
        <parent link="trunk"/>
        <child link="FL_hip"/>
        <axis xyz="1 0 0"/>
        <dynamics damping="0.0" friction="0.0"/>
        <limit effort="23.7" lower="-1.0472" upper="1.0472" velocity="30.1"/>
    </joint>
    <joint name="FL_hip_rotor_joint" type="fixed">
        <origin rpy="0 0 0" xyz="0.11215 0.04675 0"/>
        <parent link="trunk"/>
        <child link="FL_hip_rotor"/>
    </joint>
    <link name="FL_hip">
        <visual>
        <origin rpy="0 0 0" xyz="0 0 0"/>
        <geometry>
            <mesh filename="package://go2_description/meshes/hip.dae" scale="1 1 1"/>
        </geometry>
        <!-- <material name="orange"/> -->
        </visual>
        <collision>
        <origin rpy="1.5707963267948966 0 0" xyz="0 0.0955 0"/>
        <geometry>
            <cylinder length="0.04" radius="0.046"/>
        </geometry>
        </collision>
        <inertial>
        <origin rpy="0 0 0" xyz="-0.0054 0.00194 -0.000105"/>
        <mass value="0.678"/>
        <inertia ixx="0.00048" ixy="-3.01e-06" ixz="1.11e-06" iyy="0.000884" iyz="-1.42e-06" izz="0.000596"/>
        </inertial>
    </link>
    <link name="FL_hip_rotor">
        <visual>
        <origin rpy="0 1.5707963267948966 0" xyz="0 0 0"/>
        <geometry>
            <cylinder length="0.02" radius="0.035"/>
        </geometry>
        <material name="green"/>
        </visual>
        <!-- <collision>
                    <origin rpy="0 ${PI/2.0} 0" xyz="0 0 0"/>
                    <geometry>
                        <cylinder length="0.02" radius="0.035"/>
                    </geometry>
                </collision> -->
        <inertial>
        <origin rpy="0 0 0" xyz="0.0 0.0 0.0"/>
        <mass value="0.089"/>
        <inertia ixx="0.000111842" ixy="0.0" ixz="0.0" iyy="5.9647e-05" iyz="0.0" izz="5.9647e-05"/>
        </inertial>
    </link>
    <joint name="FL_thigh_joint" type="revolute">
        <origin rpy="0 0 0" xyz="0 0.0955 0"/>
        <parent link="FL_hip"/>
        <child link="FL_thigh"/>
        <axis xyz="0 1 0"/>
        <dynamics damping="0.0" friction="0.0"/>
        <limit effort="23.7" lower="-1.5708" upper="3.4907" velocity="30.1"/>
    </joint>
    <joint name="FL_thigh_rotor_joint" type="fixed">
        <origin rpy="0 0 0" xyz="0.0 -0.00015 0"/>
        <parent link="FL_hip"/>
        <child link="FL_thigh_rotor"/>
    </joint>
    <link name="FL_thigh">
        <visual>
        <origin rpy="0 0 0" xyz="0 0 0"/>
        <geometry>
            <mesh filename="package://go2_description/meshes/thigh.dae" scale="1 1 1"/>
        </geometry>
        <!-- <material name="orange"/> -->
        </visual>
        <collision>
        <origin rpy="0 1.5707963267948966 0" xyz="0 0 -0.1065"/>
        <geometry>
            <box size="0.213 0.0245 0.034"/>
        </geometry>
        </collision>
        <inertial>
        <origin rpy="0 0 0" xyz="-0.00374 -0.0223 -0.0327"/>
        <mass value="1.152"/>
        <inertia ixx="0.00584" ixy="8.72e-05" ixz="-0.000289" iyy="0.0058" iyz="0.000808" izz="0.00103"/>
        </inertial>
    </link>
    <link name="FL_thigh_rotor">
        <visual>
        <origin rpy="1.5707963267948966 0 0" xyz="0 0 0"/>
        <geometry>
            <cylinder length="0.02" radius="0.035"/>
        </geometry>
        <material name="green"/>
        </visual>
        <!-- <collision>
                    <origin rpy="${PI/2.0} 0 0" xyz="0 0 0"/>
                    <geometry>
                        <cylinder length="0.02" radius="0.035"/>
                    </geometry>
                </collision> -->
        <inertial>
        <origin rpy="0 0 0" xyz="0.0 0.0 0.0"/>
        <mass value="0.089"/>
        <inertia ixx="5.9647e-05" ixy="0.0" ixz="0.0" iyy="0.000111842" iyz="0.0" izz="5.9647e-05"/>
        </inertial>
    </link>
    <joint name="FL_calf_joint" type="revolute">
        <origin rpy="0 0 0" xyz="0 0 -0.213"/>
        <parent link="FL_thigh"/>
        <child link="FL_calf"/>
        <axis xyz="0 1 0"/>
        <dynamics damping="0.0" friction="0.0"/>
        <limit effort="35.55" lower="-2.7227" upper="-0.83776" velocity="20.06"/>
    </joint>
    <joint name="FL_calf_rotor_joint" type="fixed">
        <origin rpy="0 0 0" xyz="0.0 -0.03235 0"/>
        <parent link="FL_thigh"/>
        <child link="FL_calf_rotor"/>
    </joint>
    <link name="FL_calf">
        <visual>
        <origin rpy="0 0 0" xyz="0 0 0"/>
        <geometry>
            <mesh filename="package://go2_description/meshes/calf.dae" scale="1 1 1"/>
        </geometry>
        <!-- <material name="orange"/> -->
        </visual>
        <collision>
        <origin rpy="0 1.5707963267948966 0" xyz="0 0 -0.1065"/>
        <geometry>
            <box size="0.213 0.016 0.016"/>
        </geometry>
        </collision>
        <inertial>
        <origin rpy="0 0 0" xyz="0.00548 -0.000975 -0.115"/>
        <mass value="0.154"/>
        <inertia ixx="0.00108" ixy="3.4e-07" ixz="1.72e-05" iyy="0.0011" iyz="8.28e-06" izz="3.29e-05"/>
        </inertial>
    </link>
    <link name="FL_calf_rotor">
        <visual>
        <origin rpy="1.5707963267948966 0 0" xyz="0 0 0"/>
        <geometry>
            <cylinder length="0.02" radius="0.035"/>
        </geometry>
        <material name="green"/>
        </visual>
        <!-- <collision>
                    <origin rpy="${PI/2.0} 0 0" xyz="0 0 0"/>
                    <geometry>
                        <cylinder length="0.02" radius="0.035"/>
                    </geometry>
                </collision> -->
        <inertial>
        <origin rpy="0 0 0" xyz="0.0 0.0 0.0"/>
        <mass value="0.089"/>
        <inertia ixx="5.9647e-05" ixy="0.0" ixz="0.0" iyy="0.000111842" iyz="0.0" izz="5.9647e-05"/>
        </inertial>
    </link>
    <joint name="FL_foot_fixed" type="fixed">
        <origin rpy="0 0 0" xyz="0 0 -0.213"/>
        <parent link="FL_calf"/>
        <child link="FL_foot"/>
    </joint>
    <link name="FL_foot">
        <visual>
        <origin rpy="0 0 0" xyz="0 0 0"/>
        <geometry>
            <sphere radius="0.01"/>
        </geometry>
        <!-- <material name="orange"/> -->
        </visual>
        <collision>
        <origin rpy="0 0 0" xyz="0 0 0"/>
        <geometry>
            <sphere radius="0.02"/>
        </geometry>
        </collision>
        <inertial>
        <mass value="0.06"/>
        <inertia ixx="9.600000000000001e-06" ixy="0.0" ixz="0.0" iyy="9.600000000000001e-06" iyz="0.0" izz="9.600000000000001e-06"/>
        </inertial>
    </link>
    <xacro:leg_transmission name="FL"/>
  

    <joint name="RR_hip_joint" type="revolute">
        <origin rpy="0 0 0" xyz="-0.1934 -0.0465 0"/>
        <parent link="trunk"/>
        <child link="RR_hip"/>
        <axis xyz="-1 0 0"/>
        <dynamics damping="0.0" friction="0.0"/>
        <limit effort="23.7" lower="-1.0472" upper="1.0472" velocity="30.1"/>
    </joint>
    <joint name="RR_hip_rotor_joint" type="fixed">
        <origin rpy="0 0 0" xyz="-0.11215 -0.04675 0"/>
        <parent link="trunk"/>
        <child link="RR_hip_rotor"/>
    </joint>
    <link name="RR_hip">
        <visual>
        <origin rpy="3.141592653589793 3.141592653589793 0" xyz="0 0 0"/>
        <geometry>
            <mesh filename="package://go2_description/meshes/hip.dae" scale="1 1 1"/>
        </geometry>
        <!-- <material name="orange"/> -->
        </visual>
        <collision>
        <origin rpy="1.5707963267948966 0 0" xyz="0 -0.0955 0"/>
        <geometry>
            <cylinder length="0.04" radius="0.046"/>
        </geometry>
        </collision>
        <inertial>
        <origin rpy="0 0 0" xyz="0.0054 -0.00194 -0.000105"/>
        <mass value="0.678"/>
        <inertia ixx="0.00048" ixy="-3.01e-06" ixz="-1.11e-06" iyy="0.000884" iyz="1.42e-06" izz="0.000596"/>
        </inertial>
    </link>
    <link name="RR_hip_rotor">
        <visual>
        <origin rpy="0 1.5707963267948966 0" xyz="0 0 0"/>
        <geometry>
            <cylinder length="0.02" radius="0.035"/>
        </geometry>
        <material name="green"/>
        </visual>
        <!-- <collision>
                    <origin rpy="0 ${PI/2.0} 0" xyz="0 0 0"/>
                    <geometry>
                        <cylinder length="0.02" radius="0.035"/>
                    </geometry>
                </collision> -->
        <inertial>
        <origin rpy="0 0 0" xyz="0.0 0.0 0.0"/>
        <mass value="0.089"/>
        <inertia ixx="0.000111842" ixy="0.0" ixz="0.0" iyy="5.9647e-05" iyz="0.0" izz="5.9647e-05"/>
        </inertial>
    </link>
    <joint name="RR_thigh_joint" type="revolute">
        <origin rpy="0 0 0" xyz="0 -0.0955 0"/>
        <parent link="RR_hip"/>
        <child link="RR_thigh"/>
        <axis xyz="0 -1 0"/>
        <dynamics damping="0.0" friction="0.0"/>
        <limit effort="23.7" lower="-3.4907" upper="1.5708" velocity="30.1"/>
    </joint>
    <joint name="RR_thigh_rotor_joint" type="fixed">
        <origin rpy="0 0 0" xyz="0.0 0.00015 0"/>
        <parent link="RR_hip"/>
        <child link="RR_thigh_rotor"/>
    </joint>
    <link name="RR_thigh">
        <visual>
        <origin rpy="0 0 0" xyz="0 0 0"/>
        <geometry>
            <mesh filename="package://go2_description/meshes/thigh_mirror.dae" scale="1 1 1"/>
        </geometry>
        <!-- <material name="orange"/> -->
        </visual>
        <collision>
        <origin rpy="0 1.5707963267948966 0" xyz="0 0 -0.1065"/>
        <geometry>
            <box size="0.213 0.0245 0.034"/>
        </geometry>
        </collision>
        <inertial>
        <origin rpy="0 0 0" xyz="-0.00374 0.0223 -0.0327"/>
        <mass value="1.152"/>
        <inertia ixx="0.00584" ixy="-8.72e-05" ixz="-0.000289" iyy="0.0058" iyz="-0.000808" izz="0.00103"/>
        </inertial>
    </link>
    <link name="RR_thigh_rotor">
        <visual>
        <origin rpy="1.5707963267948966 0 0" xyz="0 0 0"/>
        <geometry>
            <cylinder length="0.02" radius="0.035"/>
        </geometry>
        <material name="green"/>
        </visual>
        <!-- <collision>
                    <origin rpy="${PI/2.0} 0 0" xyz="0 0 0"/>
                    <geometry>
                        <cylinder length="0.02" radius="0.035"/>
                    </geometry>
                </collision> -->
        <inertial>
        <origin rpy="0 0 0" xyz="0.0 0.0 0.0"/>
        <mass value="0.089"/>
        <inertia ixx="5.9647e-05" ixy="0.0" ixz="0.0" iyy="0.000111842" iyz="0.0" izz="5.9647e-05"/>
        </inertial>
    </link>
    <joint name="RR_calf_joint" type="revolute">
        <origin rpy="0 0 0" xyz="0 0 -0.213"/>
        <parent link="RR_thigh"/>
        <child link="RR_calf"/>
        <axis xyz="0 -1 0"/>
        <dynamics damping="0.0" friction="0.0"/>
        <limit effort="35.55" lower="0.83776" upper="2.7227" velocity="20.06"/>
    </joint>
    <joint name="RR_calf_rotor_joint" type="fixed">
        <origin rpy="0 0 0" xyz="0.0 0.03235 0"/>
        <parent link="RR_thigh"/>
        <child link="RR_calf_rotor"/>
    </joint>
    <link name="RR_calf">
        <visual>
        <origin rpy="0 0 0" xyz="0 0 0"/>
        <geometry>
            <mesh filename="package://go2_description/meshes/calf.dae" scale="1 1 1"/>
        </geometry>
        <!-- <material name="orange"/> -->
        </visual>
        <collision>
        <origin rpy="0 1.5707963267948966 0" xyz="0 0 -0.1065"/>
        <geometry>
            <box size="0.213 0.016 0.016"/>
        </geometry>
        </collision>
        <inertial>
        <origin rpy="0 0 0" xyz="0.00548 -0.000975 -0.115"/>
        <mass value="0.154"/>
        <inertia ixx="0.00108" ixy="3.4e-07" ixz="1.72e-05" iyy="0.0011" iyz="8.28e-06" izz="3.29e-05"/>
        </inertial>
    </link>
    <link name="RR_calf_rotor">
        <visual>
        <origin rpy="1.5707963267948966 0 0" xyz="0 0 0"/>
        <geometry>
            <cylinder length="0.02" radius="0.035"/>
        </geometry>
        <material name="green"/>
        </visual>
        <!-- <collision>
                    <origin rpy="${PI/2.0} 0 0" xyz="0 0 0"/>
                    <geometry>
                        <cylinder length="0.02" radius="0.035"/>
                    </geometry>
                </collision> -->
        <inertial>
        <origin rpy="0 0 0" xyz="0.0 0.0 0.0"/>
        <mass value="0.089"/>
        <inertia ixx="5.9647e-05" ixy="0.0" ixz="0.0" iyy="0.000111842" iyz="0.0" izz="5.9647e-05"/>
        </inertial>
    </link>
    <joint name="RR_foot_fixed" type="fixed">
        <origin rpy="0 0 0" xyz="0 0 -0.213"/>
        <parent link="RR_calf"/>
        <child link="RR_foot"/>
    </joint>
    <link name="RR_foot">
        <visual>
        <origin rpy="0 0 0" xyz="0 0 0"/>
        <geometry>
            <sphere radius="0.01"/>
        </geometry>
        <!-- <material name="orange"/> -->
        </visual>
        <collision>
        <origin rpy="0 0 0" xyz="0 0 0"/>
        <geometry>
            <sphere radius="0.02"/>
        </geometry>
        </collision>
        <inertial>
        <mass value="0.06"/>
        <inertia ixx="9.600000000000001e-06" ixy="0.0" ixz="0.0" iyy="9.600000000000001e-06" iyz="0.0" izz="9.600000000000001e-06"/>
        </inertial>
    </link>
    <xacro:leg_transmission name="RR"/>

    <joint name="RL_hip_joint" type="revolute">
        <origin rpy="0 0 0" xyz="-0.1934 0.0465 0"/>
        <parent link="trunk"/>
        <child link="RL_hip"/>
        <axis xyz="-1 0 0"/>
        <dynamics damping="0.0" friction="0.0"/>
        <limit effort="23.7" lower="-1.0472" upper="1.0472" velocity="30.1"/>
    </joint>
    <joint name="RL_hip_rotor_joint" type="fixed">
        <origin rpy="0 0 0" xyz="-0.11215 0.04675 0"/>
        <parent link="trunk"/>
        <child link="RL_hip_rotor"/>
    </joint>
    <link name="RL_hip">
        <visual>
        <origin rpy="0 3.141592653589793 0" xyz="0 0 0"/>
        <geometry>
            <mesh filename="package://go2_description/meshes/hip.dae" scale="1 1 1"/>
        </geometry>
        <!-- <material name="orange"/> -->
        </visual>
        <collision>
        <origin rpy="1.5707963267948966 0 0" xyz="0 0.0955 0"/>
        <geometry>
            <cylinder length="0.04" radius="0.046"/>
        </geometry>
        </collision>
        <inertial>
        <origin rpy="0 0 0" xyz="0.0054 0.00194 -0.000105"/>
        <mass value="0.678"/>
        <inertia ixx="0.00048" ixy="3.01e-06" ixz="-1.11e-06" iyy="0.000884" iyz="-1.42e-06" izz="0.000596"/>
        </inertial>
    </link>
    <link name="RL_hip_rotor">
        <visual>
        <origin rpy="0 1.5707963267948966 0" xyz="0 0 0"/>
        <geometry>
            <cylinder length="0.02" radius="0.035"/>
        </geometry>
        <material name="green"/>
        </visual>
        <!-- <collision>
                    <origin rpy="0 ${PI/2.0} 0" xyz="0 0 0"/>
                    <geometry>
                        <cylinder length="0.02" radius="0.035"/>
                    </geometry>
                </collision> -->
        <inertial>
        <origin rpy="0 0 0" xyz="0.0 0.0 0.0"/>
        <mass value="0.089"/>
        <inertia ixx="0.000111842" ixy="0.0" ixz="0.0" iyy="5.9647e-05" iyz="0.0" izz="5.9647e-05"/>
        </inertial>
    </link>
    <joint name="RL_thigh_joint" type="revolute">
        <origin rpy="0 0 0" xyz="0 0.0955 0"/>
        <parent link="RL_hip"/>
        <child link="RL_thigh"/>
        <axis xyz="0 1 0"/>
        <dynamics damping="0.0" friction="0.0"/>
        <limit effort="23.7" lower="-1.5708" upper="3.4907" velocity="30.1"/>
    </joint>
    <joint name="RL_thigh_rotor_joint" type="fixed">
        <origin rpy="0 0 0" xyz="0.0 -0.00015 0"/>
        <parent link="RL_hip"/>
        <child link="RL_thigh_rotor"/>
    </joint>
    <link name="RL_thigh">
        <visual>
        <origin rpy="0 0 0" xyz="0 0 0"/>
        <geometry>
            <mesh filename="package://go2_description/meshes/thigh.dae" scale="1 1 1"/>
        </geometry>
        <!-- <material name="orange"/> -->
        </visual>
        <collision>
        <origin rpy="0 1.5707963267948966 0" xyz="0 0 -0.1065"/>
        <geometry>
            <box size="0.213 0.0245 0.034"/>
        </geometry>
        </collision>
        <inertial>
        <origin rpy="0 0 0" xyz="-0.00374 -0.0223 -0.0327"/>
        <mass value="1.152"/>
        <inertia ixx="0.00584" ixy="8.72e-05" ixz="-0.000289" iyy="0.0058" iyz="0.000808" izz="0.00103"/>
        </inertial>
    </link>
    <link name="RL_thigh_rotor">
        <visual>
        <origin rpy="1.5707963267948966 0 0" xyz="0 0 0"/>
        <geometry>
            <cylinder length="0.02" radius="0.035"/>
        </geometry>
        <material name="green"/>
        </visual>
        <!-- <collision>
                    <origin rpy="${PI/2.0} 0 0" xyz="0 0 0"/>
                    <geometry>
                        <cylinder length="0.02" radius="0.035"/>
                    </geometry>
                </collision> -->
        <inertial>
        <origin rpy="0 0 0" xyz="0.0 0.0 0.0"/>
        <mass value="0.089"/>
        <inertia ixx="5.9647e-05" ixy="0.0" ixz="0.0" iyy="0.000111842" iyz="0.0" izz="5.9647e-05"/>
        </inertial>
    </link>
    <joint name="RL_calf_joint" type="revolute">
        <origin rpy="0 0 0" xyz="0 0 -0.213"/>
        <parent link="RL_thigh"/>
        <child link="RL_calf"/>
        <axis xyz="0 1 0"/>
        <dynamics damping="0.0" friction="0.0"/>
        <limit effort="35.55" lower="-2.7227" upper="-0.83776" velocity="20.06"/>
    </joint>
    <joint name="RL_calf_rotor_joint" type="fixed">
        <origin rpy="0 0 0" xyz="0.0 -0.03235 0"/>
        <parent link="RL_thigh"/>
        <child link="RL_calf_rotor"/>
    </joint>
    <link name="RL_calf">
        <visual>
        <origin rpy="0 0 0" xyz="0 0 0"/>
        <geometry>
            <mesh filename="package://go2_description/meshes/calf.dae" scale="1 1 1"/>
        </geometry>
        <!-- <material name="orange"/> -->
        </visual>
        <collision>
        <origin rpy="0 1.5707963267948966 0" xyz="0 0 -0.1065"/>
        <geometry>
            <box size="0.213 0.016 0.016"/>
        </geometry>
        </collision>
        <inertial>
        <origin rpy="0 0 0" xyz="0.00548 -0.000975 -0.115"/>
        <mass value="0.154"/>
        <inertia ixx="0.00108" ixy="3.4e-07" ixz="1.72e-05" iyy="0.0011" iyz="8.28e-06" izz="3.29e-05"/>
        </inertial>
    </link>
    <link name="RL_calf_rotor">
        <visual>
        <origin rpy="1.5707963267948966 0 0" xyz="0 0 0"/>
        <geometry>
            <cylinder length="0.02" radius="0.035"/>
        </geometry>
        <material name="green"/>
        </visual>
        <!-- <collision>
                    <origin rpy="${PI/2.0} 0 0" xyz="0 0 0"/>
                    <geometry>
                        <cylinder length="0.02" radius="0.035"/>
                    </geometry>
                </collision> -->
        <inertial>
        <origin rpy="0 0 0" xyz="0.0 0.0 0.0"/>
        <mass value="0.089"/>
        <inertia ixx="5.9647e-05" ixy="0.0" ixz="0.0" iyy="0.000111842" iyz="0.0" izz="5.9647e-05"/>
        </inertial>
    </link>
    <joint name="RL_foot_fixed" type="fixed">
        <origin rpy="0 0 0" xyz="0 0 -0.213"/>
        <parent link="RL_calf"/>
        <child link="RL_foot"/>
    </joint>
    <link name="RL_foot">
        <visual>
        <origin rpy="0 0 0" xyz="0 0 0"/>
        <geometry>
            <sphere radius="0.01"/>
        </geometry>
        <!-- <material name="orange"/> -->
        </visual>
        <collision>
        <origin rpy="0 0 0" xyz="0 0 0"/>
        <geometry>
            <sphere radius="0.02"/>
        </geometry>
        </collision>
        <inertial>
        <mass value="0.06"/>
        <inertia ixx="9.600000000000001e-06" ixy="0.0" ixz="0.0" iyy="9.600000000000001e-06" iyz="0.0" izz="9.600000000000001e-06"/>
        </inertial>
    </link>
    <xacro:leg_transmission name="RL"/>

</robot>
