<?xml version="1.0" ?>
<!-- =================================================================================== -->
<!-- |    This document was autogenerated by xacro from bare_metal.xacro               | -->
<!-- |    EDITING THIS FILE BY HAND IS NOT RECOMMENDED                                 | -->
<!-- =================================================================================== -->
<robot name="bare_metal_xacro">
  <mujoco>
    <compiler balanceinertia="false" discardvisual="false" meshdir="./../../mab_description/urdf/meshes/"/>
  </mujoco>
  <material name="silver">
    <color rgba="0.700 0.700 0.700 1.000"/>
  </material>
  <material name="black">
    <color rgba="0 0 0 1.000"/>
  </material>
  <material name="red">
    <color rgba="1.0 0 0 1.000"/>
  </material>
  <!--
  LEG 1 LEFT FRONT(LF)      LEG 0 RIGHT FRONT (RF)

                    front
              \    /O____O\    /
               \  /|      |\  /
                \/ |      | \/
                   |      |
               \   |      |   /
                \  /O~~~~O\  /
                 \/  back  \/
  LEG 2 LEFT READ (LR)      LEG 3 RIGHT READ (RR)
  -->
  <!--
  ##########################################################
  ###########                               ################
  ###########          XACRO LINKS          ################
  ###########                               ################
  ##########################################################
  -->
  <!-- 
  ###########        XACRO LEG LINKS        ################
  -->
  <!--
  ##########################################################
  ###########                               ################
  ###########         XACRO JOINTS          ################
  ###########                               ################
  ##########################################################
  -->
  <!-- 
  ###########       XACRO LEG JOINTS        ################
  -->
  <!-- NOTE: If any translation rotaion of joints is changed here,
  It must be also changed in robot_state_publisher.cpp -->
  <!--
  ##########################################################
  ###########             BODY              ################
  ##########################################################
  -->
  <link name="base_link">
  </link>
  <link name="base">
    <inertial>
      <origin rpy="0 0 0" xyz="0 0 -0.0078"/>
      <mass value="4.695"/>
      <inertia ixx="0.0159" ixy="0" ixz="0" iyy="0.07546" iyz="0" izz="0.08249"/>
    </inertial>
    <visual>
      <origin rpy="0 0 0" xyz="0 0 0"/>
      <geometry>
        <mesh filename="package://mab_description/meshes/Base.stl" scale="0.001 0.001 0.001"/>
      </geometry>
      <material name="silver"/>
    </visual>
    <collision>
      <origin rpy="0 0 0" xyz="0 0 0"/>
      <geometry>
        <mesh filename="package://mab_description/meshes/Base.stl" scale="0.001 0.001 0.001"/>
      </geometry>
      <material name="silver"/>
    </collision>
  </link>
  <joint name="root_j0" type="fixed">
    <parent link="base_link"/>
    <child link="base"/>
    <origin rpy="0 0 0" xyz="0 0 0"/>
    <axis xyz="0 0 0"/>
  </joint>
  <!--
  ##########################################################
  ###########         LEGS LINKS 0-4        ################
  ##########################################################
  -->
  <link name="fr_l0">
    <inertial>
      <origin rpy="0 0 0" xyz="0.0506 -0.0067 -0.000192"/>
      <mass value="0.499"/>
      <inertia ixx="0.0003493" ixy="0" ixz="0" iyy="0.0006636" iyz="0" izz="0.000404"/>
    </inertial>
    <visual>
      <origin rpy="3.14159 0 0" xyz="0 0 0"/>
      <geometry>
        <mesh filename="package://mab_description/meshes/L0.stl" scale="0.001 0.001 0.001"/>
      </geometry>
      <material name="silver"/>
    </visual>
  </link>
  <link name="fr_l1">
    <inertial>
      <origin rpy="0 0 0" xyz="0.0442 0.0321 0.0013"/>
      <mass value="0.779"/>
      <inertia ixx="0.003755" ixy="0" ixz="0" iyy="0.0006211" iyz="0" izz="0.003607"/>
    </inertial>
    <visual>
      <origin rpy="0 0 0" xyz="0 0 0"/>
      <geometry>
        <mesh filename="package://mab_description/meshes/L1.stl" scale="0.001 0.001 0.001"/>
      </geometry>
      <material name="silver"/>
    </visual>
  </link>
  <link name="fr_l2">
    <inertial>
      <origin rpy="0 0 0" xyz="0.0183 0.1348 0.0005"/>
      <mass value="0.060"/>
      <inertia ixx="0.000277" ixy="0" ixz="0" iyy="0.0000885" iyz="0" izz="0.0002787"/>
    </inertial>
    <visual>
      <origin rpy="0 0 0" xyz="0 0 0"/>
      <geometry>
        <mesh filename="package://mab_description/meshes/L2.stl" scale="0.001 0.001 0.001"/>
      </geometry>
      <material name="red"/>
    </visual>
    <collision>
      <origin rpy="0 0 0" xyz="0 0 0"/>
      <geometry>
        <mesh filename="package://mab_description/meshes/L2.stl" scale="0.001 0.001 0.001"/>
      </geometry>
      <material name="red"/>
    </collision>
  </link>
  <link name="fl_l0">
    <inertial>
      <origin rpy="0 0 0" xyz="0.0506 -0.0067 -0.000192"/>
      <mass value="0.499"/>
      <inertia ixx="0.0003493" ixy="0" ixz="0" iyy="0.0006636" iyz="0" izz="0.000404"/>
    </inertial>
    <visual>
      <origin rpy="3.14159 0 0" xyz="0 0 0"/>
      <geometry>
        <mesh filename="package://mab_description/meshes/L0.stl" scale="0.001 0.001 0.001"/>
      </geometry>
      <material name="silver"/>
    </visual>
  </link>
  <link name="fl_l1">
    <inertial>
      <origin rpy="0 0 0" xyz="0.0442 0.0321 0.0013"/>
      <mass value="0.779"/>
      <inertia ixx="0.003755" ixy="0" ixz="0" iyy="0.0006211" iyz="0" izz="0.003607"/>
    </inertial>
    <visual>
      <origin rpy="0 0 0" xyz="0 0 0"/>
      <geometry>
        <mesh filename="package://mab_description/meshes/L1.stl" scale="0.001 0.001 0.001"/>
      </geometry>
      <material name="silver"/>
    </visual>
  </link>
  <link name="fl_l2">
    <inertial>
      <origin rpy="0 0 0" xyz="0.0183 0.1348 0.0005"/>
      <mass value="0.060"/>
      <inertia ixx="0.000277" ixy="0" ixz="0" iyy="0.0000885" iyz="0" izz="0.0002787"/>
    </inertial>
    <visual>
      <origin rpy="0 0 0" xyz="0 0 0"/>
      <geometry>
        <mesh filename="package://mab_description/meshes/L2b.stl" scale="0.001 0.001 0.001"/>
      </geometry>
      <material name="black"/>
    </visual>
    <collision>
      <origin rpy="0 0 0" xyz="0 0 0"/>
      <geometry>
        <mesh filename="package://mab_description/meshes/L2b.stl" scale="0.001 0.001 0.001"/>
      </geometry>
      <material name="black"/>
    </collision>
  </link>
  <link name="rl_l0">
    <inertial>
      <origin rpy="0 0 0" xyz="0.0506 -0.0067 -0.000192"/>
      <mass value="0.499"/>
      <inertia ixx="0.0003493" ixy="0" ixz="0" iyy="0.0006636" iyz="0" izz="0.000404"/>
    </inertial>
    <visual>
      <origin rpy="3.14159 0 0" xyz="0 0 0"/>
      <geometry>
        <mesh filename="package://mab_description/meshes/L0.stl" scale="0.001 0.001 0.001"/>
      </geometry>
      <material name="silver"/>
    </visual>
  </link>
  <link name="rl_l1">
    <inertial>
      <origin rpy="0 0 0" xyz="0.0442 0.0321 0.0013"/>
      <mass value="0.779"/>
      <inertia ixx="0.003755" ixy="0" ixz="0" iyy="0.0006211" iyz="0" izz="0.003607"/>
    </inertial>
    <visual>
      <origin rpy="0 0 0" xyz="0 0 0"/>
      <geometry>
        <mesh filename="package://mab_description/meshes/L1.stl" scale="0.001 0.001 0.001"/>
      </geometry>
      <material name="silver"/>
    </visual>
  </link>
  <link name="rl_l2">
    <inertial>
      <origin rpy="0 0 0" xyz="0.0183 0.1348 0.0005"/>
      <mass value="0.060"/>
      <inertia ixx="0.000277" ixy="0" ixz="0" iyy="0.0000885" iyz="0" izz="0.0002787"/>
    </inertial>
    <visual>
      <origin rpy="0 0 0" xyz="0 0 0"/>
      <geometry>
        <mesh filename="package://mab_description/meshes/L2.stl" scale="0.001 0.001 0.001"/>
      </geometry>
      <material name="black"/>
    </visual>
    <collision>
      <origin rpy="0 0 0" xyz="0 0 0"/>
      <geometry>
        <mesh filename="package://mab_description/meshes/L2.stl" scale="0.001 0.001 0.001"/>
      </geometry>
      <material name="black"/>
    </collision>
  </link>
  <link name="rr_l0">
    <inertial>
      <origin rpy="0 0 0" xyz="0.0506 -0.0067 -0.000192"/>
      <mass value="0.499"/>
      <inertia ixx="0.0003493" ixy="0" ixz="0" iyy="0.0006636" iyz="0" izz="0.000404"/>
    </inertial>
    <visual>
      <origin rpy="3.14159 0 0" xyz="0 0 0"/>
      <geometry>
        <mesh filename="package://mab_description/meshes/L0.stl" scale="0.001 0.001 0.001"/>
      </geometry>
      <material name="silver"/>
    </visual>
  </link>
  <link name="rr_l1">
    <inertial>
      <origin rpy="0 0 0" xyz="0.0442 0.0321 0.0013"/>
      <mass value="0.779"/>
      <inertia ixx="0.003755" ixy="0" ixz="0" iyy="0.0006211" iyz="0" izz="0.003607"/>
    </inertial>
    <visual>
      <origin rpy="0 0 0" xyz="0 0 0"/>
      <geometry>
        <mesh filename="package://mab_description/meshes/L1.stl" scale="0.001 0.001 0.001"/>
      </geometry>
      <material name="silver"/>
    </visual>
  </link>
  <link name="rr_l2">
    <inertial>
      <origin rpy="0 0 0" xyz="0.0183 0.1348 0.0005"/>
      <mass value="0.060"/>
      <inertia ixx="0.000277" ixy="0" ixz="0" iyy="0.0000885" iyz="0" izz="0.0002787"/>
    </inertial>
    <visual>
      <origin rpy="0 0 0" xyz="0 0 0"/>
      <geometry>
        <mesh filename="package://mab_description/meshes/L2b.stl" scale="0.001 0.001 0.001"/>
      </geometry>
      <material name="black"/>
    </visual>
    <collision>
      <origin rpy="0 0 0" xyz="0 0 0"/>
      <geometry>
        <mesh filename="package://mab_description/meshes/L2b.stl" scale="0.001 0.001 0.001"/>
      </geometry>
      <material name="black"/>
    </collision>
  </link>
  <!--
  ##########################################################
  ###########                               ################
  ###########             JOINTS             ###############
  ###########                               ################
  ##########################################################
  -->
  <!--
  ##########################################################
  ###########        LEGS JOINTS 0-4        ################
  ##########################################################
  -->
  <joint armature="0.01" name="fr_j0" type="continuous">
    <parent link="base"/>
    <child link="fr_l0"/>
    <origin rpy="0 0 0" xyz="0.185 -0.05 0"/>
    <axis xyz="1.0 0 0"/>
    <limit effort="10.0" lower="-10" upper="10.0" velocity="25.0"/>
  </joint>
  <joint name="fr_j1" type="continuous">
    <parent link="fr_l0"/>
    <child link="fr_l1"/>
    <origin rpy="3.14159 0 -1.57" xyz="0.0525 -0.0222 0"/>
    <!-- TODO: xyz to verification -->
    <axis xyz="1.0 0 0"/>
    <limit effort="10.0" lower="-10" upper="10.0" velocity="25.0"/>
  </joint>
  <joint name="fr_j2" type="continuous">
    <parent link="fr_l1"/>
    <child link="fr_l2"/>
    <origin rpy="3.14159 0 0" xyz="0.0757 0.18 0"/>
    <!--TODO: xyz to verification -->
    <axis xyz="1.0 0 0"/>
    <limit effort="10.0" lower="-10" upper="10.0" velocity="25.0"/>
  </joint>
  <joint armature="0.01" name="fl_j0" type="continuous">
    <parent link="base"/>
    <child link="fl_l0"/>
    <origin rpy="3.14159 0 0" xyz="0.185 0.05 0"/>
    <axis xyz="1.0 0 0"/>
    <limit effort="10.0" lower="-10" upper="10.0" velocity="25.0"/>
  </joint>
  <joint name="fl_j1" type="continuous">
    <parent link="fl_l0"/>
    <child link="fl_l1"/>
    <origin rpy="3.14159 0 -1.57" xyz="0.0525 -0.0222 0"/>
    <!-- TODO: xyz to verification -->
    <axis xyz="1.0 0 0"/>
    <limit effort="10.0" lower="-10" upper="10.0" velocity="25.0"/>
  </joint>
  <joint name="fl_j2" type="continuous">
    <parent link="fl_l1"/>
    <child link="fl_l2"/>
    <origin rpy="3.14159 0 0" xyz="0.0757 0.18 0"/>
    <!--TODO: xyz to verification -->
    <axis xyz="1.0 0 0"/>
    <limit effort="10.0" lower="-10" upper="10.0" velocity="25.0"/>
  </joint>
  <joint armature="0.01" name="rl_j0" type="continuous">
    <parent link="base"/>
    <child link="rl_l0"/>
    <origin rpy="3.14159 3.14159 0" xyz="-0.185 0.05 0"/>
    <axis xyz="1.0 0 0"/>
    <limit effort="10.0" lower="-10" upper="10.0" velocity="25.0"/>
  </joint>
  <joint name="rl_j1" type="continuous">
    <parent link="rl_l0"/>
    <child link="rl_l1"/>
    <origin rpy="3.14159 0 -1.57" xyz="0.0525 -0.0222 0"/>
    <!-- TODO: xyz to verification -->
    <axis xyz="1.0 0 0"/>
    <limit effort="10.0" lower="-10" upper="10.0" velocity="25.0"/>
  </joint>
  <joint name="rl_j2" type="continuous">
    <parent link="rl_l1"/>
    <child link="rl_l2"/>
    <origin rpy="3.14159 0 0" xyz="0.0757 0.18 0"/>
    <!--TODO: xyz to verification -->
    <axis xyz="1.0 0 0"/>
    <limit effort="10.0" lower="-10" upper="10.0" velocity="25.0"/>
  </joint>
  <joint armature="0.01" name="rr_j0" type="continuous">
    <parent link="base"/>
    <child link="rr_l0"/>
    <origin rpy="0 3.14159 0" xyz="-0.185 -0.05 0"/>
    <axis xyz="1.0 0 0"/>
    <limit effort="10.0" lower="-10" upper="10.0" velocity="25.0"/>
  </joint>
  <joint name="rr_j1" type="continuous">
    <parent link="rr_l0"/>
    <child link="rr_l1"/>
    <origin rpy="3.14159 0 -1.57" xyz="0.0525 -0.0222 0"/>
    <!-- TODO: xyz to verification -->
    <axis xyz="1.0 0 0"/>
    <limit effort="10.0" lower="-10" upper="10.0" velocity="25.0"/>
  </joint>
  <joint name="rr_j2" type="continuous">
    <parent link="rr_l1"/>
    <child link="rr_l2"/>
    <origin rpy="3.14159 0 0" xyz="0.0757 0.18 0"/>
    <!--TODO: xyz to verification -->
    <axis xyz="1.0 0 0"/>
    <limit effort="10.0" lower="-10" upper="10.0" velocity="25.0"/>
  </joint>
</robot>
