<?xml version="1.0" ?>
<robot name="silver_badger" xmlns:xacro="http://www.ros.org/wiki/xacro">
  <mujoco>
    <compiler balanceinertia="false" discardvisual="false"/>
  </mujoco>

  
  <!-- Include gazebo elements and colors-->
  <xacro:include filename="$(find mab_description)/urdf/silver_badger.gazebo.xacro" />
  
  <!-- Import Rviz colors -->
  <xacro:include filename="$(find mab_description)/urdf/materials.xacro" />

  <!-- joint limits -->
  <xacro:property name="fr_j0_limit_lower" value="-1.57"/>
  <xacro:property name="fr_j0_limit_upper" value="1.57"/>
  <xacro:property name="fr_j1_limit_lower" value="-1.57"/>
  <xacro:property name="fr_j1_limit_upper" value="1.57"/>
  <xacro:property name="fr_j2_limit_lower" value="-2.53"/>
  <xacro:property name="fr_j2_limit_upper" value="0.0"/>
  <xacro:property name="fl_j0_limit_lower" value="-1.57"/>
  <xacro:property name="fl_j0_limit_upper" value="1.57"/>
  <xacro:property name="fl_j1_limit_lower" value="-1.57"/>
  <xacro:property name="fl_j1_limit_upper" value="1.57"/>
  <xacro:property name="fl_j2_limit_lower" value="0.0"/>
  <xacro:property name="fl_j2_limit_upper" value="2.53"/>
  <xacro:property name="rl_j0_limit_lower" value="-1.57"/>
  <xacro:property name="rl_j0_limit_upper" value="1.57"/>
  <xacro:property name="rl_j1_limit_lower" value="-1.57"/>
  <xacro:property name="rl_j1_limit_upper" value="1.57"/>
  <xacro:property name="rl_j2_limit_lower" value="0.0"/>
  <xacro:property name="rl_j2_limit_upper" value="2.53"/>
  <xacro:property name="rr_j0_limit_lower" value="-1.57"/>
  <xacro:property name="rr_j0_limit_upper" value="1.57"/>
  <xacro:property name="rr_j1_limit_lower" value="-1.57"/>
  <xacro:property name="rr_j1_limit_upper" value="1.57"/>
  <xacro:property name="rr_j2_limit_lower" value="-2.53"/>
  <xacro:property name="rr_j2_limit_upper" value="0.0"/>

  <!-- max torques per joint -->
  <xacro:property name="fr_j0_max_effort" value="16"/>
  <xacro:property name="fr_j1_max_effort" value="16"/>
  <xacro:property name="fr_j2_max_effort" value="16"/>
  <xacro:property name="fl_j0_max_effort" value="16"/>
  <xacro:property name="fl_j1_max_effort" value="16"/>
  <xacro:property name="fl_j2_max_effort" value="16"/>
  <xacro:property name="rl_j0_max_effort" value="16"/>
  <xacro:property name="rl_j1_max_effort" value="16"/>
  <xacro:property name="rl_j2_max_effort" value="16"/>
  <xacro:property name="rr_j0_max_effort" value="16"/>
  <xacro:property name="rr_j1_max_effort" value="16"/>
  <xacro:property name="rr_j2_max_effort" value="16"/>

  <!-- max velocities per joint -->
  <xacro:property name="fr_j0_max_velocity" value="25"/>
  <xacro:property name="fr_j1_max_velocity" value="25"/>
  <xacro:property name="fr_j2_max_velocity" value="25"/>
  <xacro:property name="fl_j0_max_velocity" value="25"/>
  <xacro:property name="fl_j1_max_velocity" value="25"/>
  <xacro:property name="fl_j2_max_velocity" value="25"/>
  <xacro:property name="rl_j0_max_velocity" value="25"/>
  <xacro:property name="rl_j1_max_velocity" value="25"/>
  <xacro:property name="rl_j2_max_velocity" value="25"/>
  <xacro:property name="rr_j0_max_velocity" value="25"/>
  <xacro:property name="rr_j1_max_velocity" value="25"/>
  <xacro:property name="rr_j2_max_velocity" value="25"/>
  

  <!--
  ##########################################################
  ###########             BODY              ################
  ##########################################################
  -->
  <link name="base_link"/>
  <link name="body">
    <inertial>
      <origin rpy="0 0 0" xyz="0 0 0"/>
      <mass value="5.423"/>
      <inertia ixx="0.1946" ixy="0" ixz="0" iyy="0.4899" iyz="0" izz="0.6228"/>
    </inertial>
    <visual>
      <origin rpy="0 0 0" xyz="0 0 0"/>
      <geometry>
        <mesh filename="package://meshes/hb40/body.stl" scale="0.001 0.001 0.001"/>
      </geometry>
      <material name="silver"/>
    </visual>
    <collision>
      <origin rpy="0 0 0" xyz="0 0 0" />
      <geometry>
        <box size="0.22 0.2 0.1"/>
        <material name="invisible"/>
      </geometry>
    </collision>
  </link>
  <link name="rear">
    <inertial>
      <origin rpy="0 0 0" xyz="-0.038 0.075 0"/>
      <mass value="1.337"/>
      <inertia ixx="0.09" ixy="0" ixz="0" iyy="0.0835" iyz="0" izz="0.1561"/>
    </inertial>
    <visual>
      <origin rpy="0 0 0" xyz="0 0 0"/>
      <geometry>
        <mesh filename="package://meshes/hb40/rear.stl" scale="0.001 0.001 0.001"/>
      </geometry>
      <material name="silver"/>
    </visual>
    <collision>
      <origin rpy="0 0 0" xyz="-0.04 0.08 0" />
      <geometry>
        <box size="0.2 0.05 0.1"/>
        <material name="invisible"/>
      </geometry>
    </collision>
  </link>
  <joint name="sp_j0" type="continuous">
    <parent link="body"/>
    <child link="rear"/>
    <origin rpy="3.14159 0 4.71" xyz="-0.141 -0.0395 0"/>
    <axis xyz="1 0 0"/>
    <limit effort="48.0" lower="-0.785" upper="0.785" velocity="3.15"/>
  </joint>
  <joint name="root" type="fixed">
    <parent link="base_link"/>
    <child link="body"/>
  </joint>
  <!--
  ##########################################################
  ###########         LEGS LINKS 0-4        ################
  ##########################################################
  -->
  <link name="fr_l0">
    <inertial>
      <origin rpy="0 0 0" xyz="0.0557 -0.016 0"/>
      <mass value="0.645"/>
      <inertia ixx="0.0052" ixy="0" ixz="0" iyy="0.0093" iyz="0" izz="0.0065"/>
    </inertial>
    <visual>
      <origin rpy="0 0 0" xyz="0 0 0"/>
      <geometry>
        <mesh filename="package://meshes/hb40/l0r.stl" scale="0.001 0.001 0.001"/>
      </geometry>
      <material name="silver"/>
    </visual>
  </link>
  <link name="fr_l1">
    <inertial>
      <origin rpy="0 0 0" xyz="0.031 -0.016 0"/>
      <mass value="0.827"/>
      <inertia ixx="0.0330" ixy="0" ixz="0" iyy="0.0077" iyz="0" izz="0.0286"/>
    </inertial>
    <visual>
      <origin rpy="0 0 0" xyz="0 0 0"/>
      <geometry>
        <mesh filename="package://meshes/hb40/l1r.stl" scale="0.001 0.001 0.001"/>
      </geometry>
      <material name="orange"/>
    </visual>
    <collision>
      <origin rpy="0 1.57 0" xyz="0.0 0 0"/>
      <geometry>
        <cylinder length="0.08" radius="0.05"/>
      </geometry>
    </collision>
  </link>
  <link name="fr_l2">
    <inertial>
      <origin rpy="0 0 0" xyz="0.001 -0.104 -0.003"/>
      <mass value="0.118"/>
      <inertia ixx="0.0213" ixy="0" ixz="0" iyy="0.0002" iyz="0" izz="0.0212"/>
    </inertial>
    <visual>
      <origin rpy="0 0 0" xyz="0 0 0"/>
      <geometry>
        <mesh filename="package://meshes/hb40/l2r.stl" scale="0.001 0.001 0.001"/>
      </geometry>
      <material name="red"/>
    </visual>
    <collision>
      <origin rpy="1.3 0 0" xyz="0 0.01 0.0055"/>
      <geometry>
        <cylinder length="0.0625" radius="0.01"/>
      </geometry>
      <material name="invisible"/>
    </collision>
    <collision>
      <origin rpy="1.67 0.0 0.05" xyz="0 -0.1 0.005"/>
      <geometry>
        <cylinder length="0.2" radius="0.015"/>
      </geometry>
      <material name="invisible"/>
    </collision>
  </link>
    <link name="fr_foot">
    <inertial>
      <origin rpy="0 0 0" xyz="0.0 0.0 0.0"/>
      <mass value="0.0"/>
      <inertia ixx="0.0" ixy="0" ixz="0" iyy="0.0" iyz="0" izz="0.0"/>
    </inertial>
    <visual>
      <origin rpy="0 0 0" xyz="0 0 0"/>
      <geometry>
        <sphere radius="0.021"/>
      </geometry>
      <material name="black"/>
    </visual>
    <collision>
      <origin rpy="0 0 0" xyz="0 0 0"/>
      <geometry>
        <sphere radius="0.02"/>
      </geometry>
    </collision>
  </link>
  <link name="fl_l0">
    <inertial>
      <origin rpy="0 0 0" xyz="0.0557 -0.016 0"/>
      <mass value="0.645"/>
      <inertia ixx="0.0052" ixy="0" ixz="0" iyy="0.0093" iyz="0" izz="0.0065"/>
    </inertial>
    <visual>
      <origin rpy="0 0 0" xyz="0 0 0"/>
      <geometry>
        <mesh filename="package://meshes/hb40/l0l.stl" scale="0.001 0.001 0.001"/>
      </geometry>
      <material name="silver"/>
    </visual>
  </link>
  <link name="fl_l1">
    <inertial>
      <origin rpy="0 0 0" xyz="0.031 0.016 0"/>
      <mass value="0.827"/>
      <inertia ixx="0.0330" ixy="0" ixz="0" iyy="0.0077" iyz="0" izz="0.0286"/>
    </inertial>
    <visual>
      <origin rpy="0 0 0" xyz="0 0 0"/>
      <geometry>
        <mesh filename="package://meshes/hb40/l1lf.stl" scale="0.001 0.001 0.001"/>
      </geometry>
      <material name="orange"/>
    </visual>
    <collision>
      <origin rpy="0 1.57 0" xyz="0.0 0 0"/>
      <geometry>
        <cylinder length="0.08" radius="0.05"/>
      </geometry>
    </collision>
  </link>
  <link name="fl_l2">
    <inertial>
      <origin rpy="0 0 0" xyz="0.001 0.104 -0.003"/>
      <mass value="0.118"/>
      <inertia ixx="0.0213" ixy="0" ixz="0" iyy="0.0002" iyz="0" izz="0.0212"/>
    </inertial>
    <visual>
      <origin rpy="0 0 0" xyz="0 0 0"/>
      <geometry>
        <mesh filename="package://meshes/hb40/l2l.stl" scale="0.001 0.001 0.001"/>
      </geometry>
      <material name="silver"/>
    </visual>
    <collision>
      <origin rpy="-1.3 0.0 -0.00" xyz="0 -0.01 0.0055"/>
      <geometry>
        <cylinder length="0.0625" radius="0.01"/>
      </geometry>
      <material name="invisible"/>
    </collision>
    <collision>
      <origin rpy="-1.67 0.0 -0.05" xyz="0 0.1 0.005"/>
      <geometry>
        <cylinder length="0.2" radius="0.015"/>
      </geometry>
      <material name="invisible"/>
    </collision>
  </link>
  <link name="fl_foot">
    <inertial>
      <origin rpy="0 0 0" xyz="0.0 0.0 0.0"/>
      <mass value="0.0"/>
      <inertia ixx="0.0" ixy="0" ixz="0" iyy="0.0" iyz="0" izz="0.0"/>
    </inertial>
    <visual>
      <origin rpy="0 0 0" xyz="0 0 0"/>
      <geometry>
        <sphere radius="0.021"/>
      </geometry>
      <material name="black"/>
    </visual>
    <collision>
      <origin rpy="0 0 0" xyz="0 0 0"/>
      <geometry>
        <sphere radius="0.02"/>
      </geometry>
    </collision>
  </link>
  <link name="rl_l0">
    <inertial>
      <origin rpy="0 0 0" xyz="0.0557 -0.016 0"/>
      <mass value="0.645"/>
      <inertia ixx="0.0052" ixy="0" ixz="0" iyy="0.0093" iyz="0" izz="0.0065"/>
    </inertial>
    <visual>
      <origin rpy="0 0 0" xyz="0 0 0"/>
      <geometry>
        <mesh filename="package://meshes/hb40/l0l.stl" scale="0.001 0.001 0.001"/>
      </geometry>
      <material name="silver"/>
    </visual>
  </link>
  <link name="rl_l1">
    <inertial>
      <origin rpy="0 0 0" xyz="0.031 0.016 0"/>
      <mass value="0.827"/>
      <inertia ixx="0.0330" ixy="0" ixz="0" iyy="0.0077" iyz="0" izz="0.0286"/>
    </inertial>
    <visual>
      <origin rpy="0 0 0" xyz="0 0 0"/>
      <geometry>
        <mesh filename="package://meshes/hb40/l1lf.stl" scale="0.001 0.001 0.001"/>
      </geometry>
      <material name="orange"/>
    </visual>
    <collision>
      <origin rpy="0 1.57 0" xyz="0.0 0 0"/>
      <geometry>
        <cylinder length="0.08" radius="0.05"/>
      </geometry>
    </collision>
  </link>
  <link name="rl_l2">
    <inertial>
      <origin rpy="0 0 0" xyz="0.001 0.104 -0.003"/>
      <mass value="0.118"/>
      <inertia ixx="0.0213" ixy="0" ixz="0" iyy="0.0002" iyz="0" izz="0.0212"/>
    </inertial>
    <visual>
      <origin rpy="0 0 0" xyz="0 0 0"/>
      <geometry>
        <mesh filename="package://meshes/hb40/l2l.stl" scale="0.001 0.001 0.001"/>
      </geometry>
      <material name="silver"/>
    </visual>
    <collision>
      <origin rpy="-1.3 0 0" xyz="0 -0.01 0.0055"/>
      <geometry>
        <cylinder length="0.0625" radius="0.01"/>
      </geometry>
      <material name="invisible"/>
    </collision>
    <collision>
      <origin rpy="-1.67 0.0 -0.05" xyz="0 0.1 0.005"/>
      <geometry>
        <cylinder length="0.2" radius="0.015"/>
        <material name="invisible"/>
      </geometry>
    </collision>
  </link>
  <link name="rl_foot">
    <inertial>
      <origin rpy="0 0 0" xyz="0.0 0.0 0.0"/>
      <mass value="0.0"/>
      <inertia ixx="0.0" ixy="0" ixz="0" iyy="0.0" iyz="0" izz="0.0"/>
    </inertial>
    <visual>
      <origin rpy="0 0 0" xyz="0 0 0"/>
      <geometry>
        <sphere radius="0.021"/>
      </geometry>
      <material name="black"/>
    </visual>
    <collision>
      <origin rpy="0 0 0" xyz="0 0 0"/>
      <geometry>
        <sphere radius="0.02"/>
      </geometry>
    </collision>
  </link>
  <link name="rr_l0">
    <inertial>
      <origin rpy="0 0 0" xyz="0.0557 -0.016 0"/>
      <mass value="0.645"/>
      <inertia ixx="0.0052" ixy="0" ixz="0" iyy="0.0093" iyz="0" izz="0.0065"/>
    </inertial>
    <visual>
      <origin rpy="0 0 0" xyz="0 0 0"/>
      <geometry>
        <mesh filename="package://meshes/hb40/l0r.stl" scale="0.001 0.001 0.001"/>
      </geometry>
      <material name="silver"/>
    </visual>
  </link>
  <link name="rr_l1">
    <inertial>
      <origin rpy="0 0 0" xyz="0.031 -0.016 0"/>
      <mass value="0.827"/>
      <inertia ixx="0.0330" ixy="0" ixz="0" iyy="0.0077" iyz="0" izz="0.0286"/>
    </inertial>
    <visual>
      <origin rpy="0 0 0" xyz="0 0 0"/>
      <geometry>
        <mesh filename="package://meshes/hb40/l1r.stl" scale="0.001 0.001 0.001"/>
      </geometry>
      <material name="orange"/>
    </visual>
    <collision>
      <origin rpy="0 1.57 0" xyz="0.0 0 0"/>
      <geometry>
        <cylinder length="0.08" radius="0.05"/>
      </geometry>
    </collision>
  </link>
  <link name="rr_l2">
    <inertial>
      <origin rpy="0 0 0" xyz="0.001 -0.104 -0.003"/>
      <mass value="0.118"/>
      <inertia ixx="0.0213" ixy="0" ixz="0" iyy="0.0002" iyz="0" izz="0.0212"/>
    </inertial>
    <visual>
      <origin rpy="0 0 0" xyz="0 0 0"/>
      <geometry>
        <mesh filename="package://meshes/hb40/l2r.stl" scale="0.001 0.001 0.001"/>
      </geometry>
      <material name="silver"/>
    </visual>
    <collision>
      <origin rpy="1.3 0.0 0" xyz="0 0.01 0.0055"/>
      <geometry>
        <cylinder length="0.0625" radius="0.01"/>
        <material name="invisible"/>
      </geometry>
    </collision>
    <collision>
      <origin rpy="1.67 0.0 0.05" xyz="0 -0.1 0.005"/>
      <geometry>
        <cylinder length="0.2" radius="0.015"/>
        <material name="invisible"/>
      </geometry>
    </collision>
  </link>
  <link name="rr_foot">
    <inertial>
      <origin rpy="0 0 0" xyz="0.0 0.0 0.0"/>
      <mass value="0.0"/>
      <inertia ixx="0.0" ixy="0" ixz="0" iyy="0.0" iyz="0" izz="0.0"/>
    </inertial>
    <visual>
      <origin rpy="0 0 0" xyz="0 0 0"/>
      <geometry>
        <sphere radius="0.021"/>
      </geometry>
      <material name="black"/>
    </visual>
    <collision>
      <origin rpy="0 0 0" xyz="0 0 0"/>
      <geometry>
        <sphere radius="0.02"/>
      </geometry>
    </collision>
  </link>
  <!--
  ##########################################################
  ###########        LEGS JOINTS 0-4        ################
  ##########################################################
  -->
  <!-- Front Right Leg -->
  <joint armature="0.01" name="fr_j0" type="continuous">
    <parent link="body"/>
    <child link="fr_l0"/>
    <origin rpy="0 0 0" xyz="0.1375 -0.064 0"/>
    <axis xyz="1.0 0 0"/>
    <limit effort="${fr_j0_max_effort}" lower="${fr_j0_limit_lower}" upper="${fr_j0_limit_upper}" velocity="${fr_j0_max_velocity}"/>
  </joint>
  <joint name="fr_j1" type="continuous">
    <parent link="fr_l0"/>
    <child link="fr_l1"/>
    <origin rpy="0 0 -1.57" xyz="0.0555 -0.0125 0"/>
    <axis xyz="1.0 0 0"/>
    <limit effort="${fr_j1_max_effort}" lower="${fr_j1_limit_lower}" upper="${fr_j1_limit_upper}" velocity="${fr_j1_max_velocity}"/>
  </joint>
  <joint name="fr_j2" type="continuous">
    <parent link="fr_l1"/>
    <child link="fr_l2"/>
    <origin rpy="2.909 0 0" xyz="0.0584 -0.200 0"/>
    <axis xyz="1.0 0 0"/>
    <limit effort="${fr_j2_max_effort}" lower="${fr_j2_limit_lower}" upper="${fr_j2_limit_upper}" velocity="${fr_j2_max_velocity}"/>
  </joint>
  <joint name="fr_jFoot" type="fixed">
    <parent link="fr_l2"/>
    <child link="fr_foot"/>
    <origin rpy="0 0 0" xyz="0.0054 -0.200 0"/>
    <axis xyz="0.0 0 0"/>
  </joint>

  <!-- Front Left Leg -->
  <joint armature="0.01" name="fl_j0" type="continuous">
    <parent link="body"/>
    <child link="fl_l0"/>
    <origin rpy="0 0 0" xyz="0.1375 0.064 0"/>
    <axis xyz="1.0 0 0"/>
    <limit effort="${fl_j0_max_effort}" lower="${fl_j0_limit_lower}" upper="${fl_j0_limit_upper}" velocity="${fl_j0_max_velocity}"/>
  </joint>
  <joint name="fl_j1" type="continuous">
    <parent link="fl_l0"/>
    <child link="fl_l1"/>
    <origin rpy="0 0 1.57" xyz="0.0555 0.0125 0"/>
    <axis xyz="1.0 0 0"/>
    <limit effort="${fl_j1_max_effort}" lower="${fl_j1_limit_lower}" upper="${fl_j1_limit_upper}" velocity="${fl_j1_max_velocity}"/>
  </joint>
  <joint name="fl_j2" type="continuous">
    <parent link="fl_l1"/>
    <child link="fl_l2"/>
    <origin rpy="-2.909 0 0" xyz="0.0584 0.200 0"/>
    <axis xyz="1.0 0 0"/>
    <limit effort="${fl_j2_max_effort}" lower="${fl_j2_limit_lower}" upper="${fl_j2_limit_upper}" velocity="${fl_j2_max_velocity}"/>
  </joint> 
  <joint name="fl_jFoot" type="fixed">
    <parent link="fl_l2"/>
    <child link="fl_foot"/>
    <origin rpy="0 0 0" xyz="0.0054 0.200 0"/>
    <axis xyz="0.0 0 0"/>
  </joint>

  <!-- Rear Left Leg -->
  <joint armature="0.01" name="rl_j0" type="continuous">
    <parent link="rear"/>
    <child link="rl_l0"/>
    <origin rpy="0 0 1.57" xyz="-0.1025 0.10765 0"/>
    <axis xyz="1.0 0 0"/>
    <limit effort="${rl_j0_max_effort}" lower="${rl_j0_limit_lower}" upper="${rl_j0_limit_upper}" velocity="${rl_j0_max_velocity}"/>
  </joint>
  <joint name="rl_j1" type="continuous">
    <parent link="rl_l0"/>
    <child link="rl_l1"/>
    <origin rpy="3.14159 0 1.57" xyz="0.0555 0.0125 0"/>
    <axis xyz="1.0 0 0"/>
    <limit effort="${rl_j1_max_effort}" lower="${rl_j1_limit_lower}" upper="${rl_j1_limit_upper}" velocity="${rl_j1_max_velocity}"/>
  </joint>
  <joint name="rl_j2" type="continuous">
    <parent link="rl_l1"/>
    <child link="rl_l2"/>
    <origin rpy="-2.909 0 0" xyz="0.0584 0.20 0"/>
    <axis xyz="1.0 0 0"/>
    <limit effort="${rl_j2_max_effort}" lower="${rl_j2_limit_lower}" upper="${rl_j2_limit_upper}" velocity="${rl_j2_max_velocity}"/>
  </joint>
  <joint name="rl_jFoot" type="fixed">
    <parent link="rl_l2"/>
    <child link="rl_foot"/>
    <origin rpy="0 0 0" xyz="0.0054 0.200 0"/>
    <axis xyz="0.0 0 0"/>
  </joint>

  <!-- Rear Right Leg -->
  <joint armature="0.01" name="rr_j0" type="continuous">
    <parent link="rear"/>
    <child link="rr_l0"/>
    <origin rpy="0 0 1.57" xyz="0.0255 0.10725 0"/>
    <axis xyz="1.0 0 0"/>
    <limit effort="${rr_j0_max_effort}" lower="${rr_j0_limit_lower}" upper="${rr_j0_limit_upper}" velocity="${rr_j0_max_velocity}"/>
  </joint>
  <joint name="rr_j1" type="continuous">
    <parent link="rr_l0"/>
    <child link="rr_l1"/>
    <origin rpy="3.14159 0 -1.57" xyz="0.0555 -0.0125 0"/>
    <axis xyz="1.0 0 0"/>
    <limit effort="${rr_j1_max_effort}" lower="${rr_j1_limit_lower}" upper="${rr_j1_limit_upper}" velocity="${rr_j1_max_velocity}"/>
  </joint>
  <joint name="rr_j2" type="continuous">
    <parent link="rr_l1"/>
    <child link="rr_l2"/>
    <origin rpy="2.909 0 0" xyz="0.0584 -0.20 0"/>
    <axis xyz="1.0 0 0"/>
    <limit effort="${rr_j2_max_effort}" lower="${rr_j2_limit_lower}" upper="${rr_j2_limit_upper}" velocity="${rr_j2_max_velocity}"/>
  </joint>
  <joint name="rr_jFoot" type="fixed">
    <parent link="rr_l2"/>
    <child link="rr_foot"/>
    <origin rpy="0 0 0" xyz="0.0054 -0.200 0"/>
    <axis xyz="0.0 0 0"/>
  </joint>
</robot>
