<?xml version="1.0" ?>
<!-- =================================================================================== -->
<!-- |    This document was autogenerated by xacro from src/mab_ros/mab_description/xacro/honey_badger.urdf.xacro | -->
<!-- |    EDITING THIS FILE BY HAND IS NOT RECOMMENDED                                 | -->
<!-- =================================================================================== -->
<robot name="honey_badger">
  <mujoco>
    <compiler balanceinertia="false" discardvisual="false" meshdir="file:///home/junninghuang/ros2_ws/install/mab_description/share/mab_description/meshes/hb40/"/>
  </mujoco>
  <!-- Colors-->
  <gazebo reference="body">
    <mu1>0.2</mu1>
    <mu2>0.2</mu2>
    <material>Gazebo/Grey</material>
  </gazebo>
  <gazebo reference="rear">
    <mu1>0.2</mu1>
    <mu2>0.2</mu2>
    <material>Gazebo/Grey</material>
  </gazebo>
  <gazebo reference="fr_l0">
    <mu1>0.2</mu1>
    <mu2>0.2</mu2>
    <material>Gazebo/Grey</material>
  </gazebo>
  <gazebo reference="fr_l1">
    <mu1>0.2</mu1>
    <mu2>0.2</mu2>
    <material>Gazebo/Orange</material>
  </gazebo>
  <gazebo reference="fr_l2">
    <mu1>0.2</mu1>
    <mu2>0.2</mu2>
    <material>Gazebo/Grey</material>
  </gazebo>
  <gazebo reference="fr_foot">
    <mu1>0.6</mu1>
    <mu2>0.6</mu2>
    <self_collide>0</self_collide>
    <kp value="1000000.0"/>
    <kd value="1.0"/>
    <material>Gazebo/Black</material>
  </gazebo>
  <gazebo reference="fl_l0">
    <mu1>0.2</mu1>
    <mu2>0.2</mu2>
    <material>Gazebo/Grey</material>
  </gazebo>
  <gazebo reference="fl_l1">
    <mu1>0.2</mu1>
    <mu2>0.2</mu2>
    <material>Gazebo/Orange</material>
  </gazebo>
  <gazebo reference="fl_l2">
    <mu1>0.2</mu1>
    <mu2>0.2</mu2>
    <material>Gazebo/Grey</material>
  </gazebo>
  <gazebo reference="fl_foot">
    <mu1>0.6</mu1>
    <mu2>0.6</mu2>
    <self_collide>0</self_collide>
    <kp value="1000000.0"/>
    <kd value="1.0"/>
    <material>Gazebo/Black</material>
  </gazebo>
  <gazebo reference="rl_l0">
    <mu1>0.2</mu1>
    <mu2>0.2</mu2>
    <material>Gazebo/Grey</material>
  </gazebo>
  <gazebo reference="rl_l1">
    <mu1>0.2</mu1>
    <mu2>0.2</mu2>
    <material>Gazebo/Orange</material>
  </gazebo>
  <gazebo reference="rl_l2">
    <mu1>0.2</mu1>
    <mu2>0.2</mu2>
    <material>Gazebo/Grey</material>
  </gazebo>
  <gazebo reference="rl_foot">
    <mu1>0.6</mu1>
    <mu2>0.6</mu2>
    <self_collide>0</self_collide>
    <kp value="1000000.0"/>
    <kd value="1.0"/>
    <material>Gazebo/Black</material>
  </gazebo>
  <gazebo reference="rr_l0">
    <mu1>0.2</mu1>
    <mu2>0.2</mu2>
    <material>Gazebo/Grey</material>
  </gazebo>
  <gazebo reference="rr_l1">
    <mu1>0.2</mu1>
    <mu2>0.2</mu2>
    <material>Gazebo/Orange</material>
  </gazebo>
  <gazebo reference="rr_l2">
    <mu1>0.2</mu1>
    <mu2>0.2</mu2>
    <material>Gazebo/Grey</material>
  </gazebo>
  <gazebo reference="rr_foot">
    <mu1>0.6</mu1>
    <mu2>0.6</mu2>
    <self_collide>0</self_collide>
    <kp value="1000000.0"/>
    <kd value="1.0"/>
    <material>Gazebo/Black</material>
  </gazebo>
  <gazebo reference="camera_mount">
    <material>Gazebo/DarkGrey</material>
  </gazebo>
  <gazebo reference="camera_interface">
    <material>Gazebo/DarkGrey</material>
  </gazebo>
  <!-- Controllers-->
  <!-- <gazebo>
      <plugin name="gazebo_ros2_control" filename="libgazebo_ros2_control.so">
        <parameters>$(find mab_gazebo)/config/silver_badger_controller.yaml</parameters>
      </plugin>
    </gazebo> -->
  <gazebo>
    <plugin filename="libmab_control.so" name="mab_gazebo_plugin">
      <robot>honey_badger</robot>
    </plugin>
  </gazebo>
  <gazebo reference="imu_link">
    <!-- <gazebo reference="d435i_camera_accel_frame"> -->
    <gravity>true</gravity>
    <sensor name="imu_sensor" type="imu">
      <always_on>1</always_on>
      <update_rate>100</update_rate>
      <visualize>1</visualize>
      <topic>imu</topic>
      <plugin filename="libgazebo_ros_imu_sensor.so" name="imu">
        <topicName>imu</topicName>
        <bodyName>imu_sensor_link</bodyName>
        <updateRateHZ>100.0</updateRateHZ>
        <xyzOffset>0 0 0</xyzOffset>
        <rpyOffset>0 0 0</rpyOffset>
      </plugin>
      <pose>0 0 0 0 0 0</pose>
    </sensor>
  </gazebo>
  <!-- <gazebo reference="d435i_camera_accel_frame">
      <gravity>true</gravity>
      <sensor name='cam_imu_sensor' type='imu'>
          <always_on>1</always_on>
          <update_rate>100</update_rate>
          <visualize>1</visualize>
          <topic>cam_imu</topic>
          <plugin name='cam_imu' filename='libgazebo_ros_imu_sensor.so'>
              <topicName>cam_imu</topicName>
              <bodyName>cam_imu_sensor_link</bodyName>
              <updateRateHZ>100.0</updateRateHZ>
              <xyzOffset>0 0 0</xyzOffset>
              <rpyOffset>0 0 0</rpyOffset>
          </plugin>
          <pose>0 0 0 0 0 0</pose>
      </sensor>
    </gazebo> -->
  <!-- Foot Contact Sensors-->
  <gazebo reference="fr_foot">
    <sensor name="fr_foot_bumper" type="contact">
      <selfCollide>true</selfCollide>
      <alwaysOn>true</alwaysOn>
      <updateRate>50.0</updateRate>
      <material>Gazebo/Red</material>
      <contact>
        <collision>fr_l2_fixed_joint_lump__fr_foot_collision_2</collision>
      </contact>
      <plugin filename="libgazebo_ros_bumper.so" name="gazebo_ros_bumper_controller_fr_foot">
        <ros>
          <remapping>bumper_states:=feet_contact</remapping>
        </ros>
      </plugin>
    </sensor>
  </gazebo>
  <gazebo reference="fl_foot">
    <sensor name="fl_foot_bumper" type="contact">
      <selfCollide>true</selfCollide>
      <alwaysOn>true</alwaysOn>
      <updateRate>50.0</updateRate>
      <material>Gazebo/Red</material>
      <contact>
        <collision>fl_l2_fixed_joint_lump__fl_foot_collision_2</collision>
      </contact>
      <plugin filename="libgazebo_ros_bumper.so" name="gazebo_ros_bumper_controller_fl_foot">
        <ros>
          <remapping>bumper_states:=feet_contact</remapping>
        </ros>
      </plugin>
    </sensor>
  </gazebo>
  <gazebo reference="rr_foot">
    <sensor name="rr_foot_bumper" type="contact">
      <selfCollide>true</selfCollide>
      <alwaysOn>true</alwaysOn>
      <updateRate>50.0</updateRate>
      <material>Gazebo/Red</material>
      <contact>
        <collision> </collision>
      </contact>
      <plugin filename="libgazebo_ros_bumper.so" name="gazebo_ros_bumper_controller_rr_foot">
        <ros>
          <remapping>bumper_states:=feet_contact</remapping>
        </ros>
      </plugin>
    </sensor>
  </gazebo>
  <gazebo reference="rl_foot">
    <sensor name="rl_foot_bumper" type="contact">
      <selfCollide>true</selfCollide>
      <alwaysOn>true</alwaysOn>
      <updateRate>50.0</updateRate>
      <material>Gazebo/Red</material>
      <contact>
        <collision>rl_l2_fixed_joint_lump__rl_foot_collision_2</collision>
      </contact>
      <plugin filename="libgazebo_ros_bumper.so" name="gazebo_ros_bumper_controller_rl_foot">
        <ros>
          <remapping>bumper_states:=feet_contact</remapping>
        </ros>
      </plugin>
    </sensor>
  </gazebo>
  <!-- Ground truth odom-->
  <gazebo>
    <plugin filename="libgazebo_ros_p3d.so" name="gazebo_ros_p3d">
      <ros>
        <remapping>odom:=odom_gt</remapping>
      </ros>
      <body_name>base_link</body_name>
      <frame_name>world</frame_name>
      <update_rate>50</update_rate>
      <xyz_offset>0 0 0</xyz_offset>
      <rpy_offset>0 0 0</rpy_offset>
      <gaussian_noise>0.0</gaussian_noise>
    </plugin>
  </gazebo>
  <material name="silver">
    <color rgba="0.600 0.600 0.600 1.000"/>
  </material>
  <material name="black">
    <color rgba="0.1 0.1 0.1 1.000"/>
  </material>
  <material name="red">
    <color rgba="1.0 0 0 1.000"/>
  </material>
  <material name="orange">
    <color rgba="1.0 0.41 0 1.000"/>
  </material>
  <material name="invisible">
    <color rgba="0 0 0 0"/>
  </material>
  <!-- Import control tags-->
  <!-- <xacro:include filename="$(find mab_description)/xacro/control.xacro" /> -->
  <!-- Initialize controls-->
  <!-- <xacro:silver_badger_ros2_control/> -->
  <!-- BODY  -->
  <link name="base_link"/>
  <link name="body">
    <!-- <inertial>
      <origin rpy="0 0 0" xyz="0 0 0"/>
      <mass value="5.423"/>
      <inertia ixx="0.1946" ixy="0" ixz="0" iyy="0.4899" iyz="0" izz="0.6228"/>
    </inertial> -->
    <inertial>
      <origin xyz="1.18875861e-3 -0.27765860e-3 3.26127652e-3"/>
      <mass value="5.42300000"/>
      <inertia ixx="23739.22164296e-6" ixy="-1.75184170e-6" ixz="-1.21903766e-6" iyy="35834.63679865e-6" iyz="-0.76849991e-6" izz="51509.07488697e-6"/>
    </inertial>
    <visual>
      <origin rpy="0 0 0" xyz="0 0 0"/>
      <geometry>
        <mesh filename="file:///home/junninghuang/ros2_ws/install/mab_description/share/mab_description/meshes/hb40/hb40.stl" scale="0.001 0.001 0.001"/>
      </geometry>
      <material name="silver"/>
    </visual>
    <collision>
      <geometry>
        <box size="0.27 0.178 0.1"/>
      </geometry>
    </collision>
  </link>
  <joint name="root" type="fixed">
    <parent link="base_link"/>
    <child link="body"/>
  </joint>
  <link name="camera_mount">
    <inertial>
      <origin xyz="0 0 0"/>
      <mass value="0"/>
      <inertia ixx="0" ixy="0" ixz="0" iyy="0" iyz="0" izz="0"/>
    </inertial>
    <visual>
      <origin rpy="0 0 1.5707963267948966" xyz="0.11501 0.000167 0.024886"/>
      <geometry>
        <mesh filename="file:///home/junninghuang/ros2_ws/install/mab_description/share/mab_description/meshes/camera_mount/hb-camera-mount.stl"/>
      </geometry>
      <material name="silver"/>
    </visual>
  </link>
  <joint name="camera_mount_joint" type="fixed">
    <parent link="body"/>
    <child link="camera_mount"/>
  </joint>
  <link name="camera_interface">
    <inertial>
      <origin xyz="0 0 0"/>
      <mass value="0"/>
      <inertia ixx="0" ixy="0" ixz="0" iyy="0" iyz="0" izz="0"/>
    </inertial>
    <visual>
      <origin rpy="1.5707963267948966 3.141592653589793 1.5707963267948966" xyz="0.26171 0.000167 0.068486"/>
      <geometry>
        <mesh filename="file:///home/junninghuang/ros2_ws/install/mab_description/share/mab_description/meshes/camera_mount/camera-interface-realsense-and-oak.stl" scale="0.001 0.001 0.001"/>
      </geometry>
      <material name="silver"/>
    </visual>
  </link>
  <joint name="camera_interface_joint" type="fixed">
    <parent link="body"/>
    <child link="camera_interface"/>
  </joint>
  <!-- <xacro:property name="d435_cam_roll" value="0"/> -->
  <material name="aluminum">
    <color rgba="0.5 0.5 0.5 1"/>
  </material>
  <material name="plastic">
    <color rgba="0.1 0.1 0.1 1"/>
  </material>
  <!-- camera body, with origin at bottom screw mount -->
  <joint name="d435i_camera_joint" type="fixed">
    <origin rpy="-1.5707963267948966 0 0" xyz="0.275855 -0.012447000000000001 0.068583"/>
    <parent link="body"/>
    <child link="d435i_camera_bottom_screw_frame"/>
  </joint>
  <link name="d435i_camera_bottom_screw_frame"/>
  <joint name="d435i_camera_link_joint" type="fixed">
    <origin rpy="0 0 0" xyz="0.010600000000000002 0.0175 0.0125"/>
    <parent link="d435i_camera_bottom_screw_frame"/>
    <child link="d435i_camera_link"/>
  </joint>
  <link name="d435i_camera_link">
    <visual>
      <!-- the mesh origin is at front plate in between the two infrared camera axes -->
      <origin rpy="1.5707963267948966 0 1.5707963267948966" xyz="0.0043 -0.0175 0"/>
      <geometry>
        <mesh filename="file:///home/junninghuang/ros2_ws/install/realsense2_description/share/realsense2_description/meshes/d435.dae"/>
      </geometry>
    </visual>
    <collision>
      <origin rpy="0 0 0" xyz="0 -0.0175 0"/>
      <geometry>
        <box size="0.02505 0.09 0.025"/>
      </geometry>
    </collision>
    <inertial>
      <!-- The following are not reliable values, and should not be used for modeling -->
      <mass value="0.072"/>
      <origin xyz="0 0 0"/>
      <inertia ixx="0.003881243" ixy="0.0" ixz="0.0" iyy="0.000498940" iyz="0.0" izz="0.003879257"/>
    </inertial>
  </link>
  <!-- camera depth joints and links -->
  <joint name="d435i_camera_depth_joint" type="fixed">
    <origin rpy="0 0 0" xyz="0 0 0"/>
    <parent link="d435i_camera_link"/>
    <child link="d435i_camera_depth_frame"/>
  </joint>
  <link name="d435i_camera_depth_frame"/>
  <joint name="d435i_camera_depth_optical_joint" type="fixed">
    <origin rpy="-1.5707963267948966 0 -1.5707963267948966" xyz="0 0 0"/>
    <parent link="d435i_camera_depth_frame"/>
    <child link="d435i_camera_depth_optical_frame"/>
  </joint>
  <link name="d435i_camera_depth_optical_frame"/>
  <!-- camera left IR joints and links -->
  <joint name="d435i_camera_infra1_joint" type="fixed">
    <origin rpy="0 0 0" xyz="0 0.0 0"/>
    <parent link="d435i_camera_link"/>
    <child link="d435i_camera_infra1_frame"/>
  </joint>
  <link name="d435i_camera_infra1_frame"/>
  <joint name="d435i_camera_infra1_optical_joint" type="fixed">
    <origin rpy="-1.5707963267948966 0 -1.5707963267948966" xyz="0 0 0"/>
    <parent link="d435i_camera_infra1_frame"/>
    <child link="d435i_camera_infra1_optical_frame"/>
  </joint>
  <link name="d435i_camera_infra1_optical_frame"/>
  <!-- camera right IR joints and links -->
  <joint name="d435i_camera_infra2_joint" type="fixed">
    <origin rpy="0 0 0" xyz="0 -0.05 0"/>
    <parent link="d435i_camera_link"/>
    <child link="d435i_camera_infra2_frame"/>
  </joint>
  <link name="d435i_camera_infra2_frame"/>
  <joint name="d435i_camera_infra2_optical_joint" type="fixed">
    <origin rpy="-1.5707963267948966 0 -1.5707963267948966" xyz="0 0 0"/>
    <parent link="d435i_camera_infra2_frame"/>
    <child link="d435i_camera_infra2_optical_frame"/>
  </joint>
  <link name="d435i_camera_infra2_optical_frame"/>
  <!-- camera color joints and links -->
  <joint name="d435i_camera_color_joint" type="fixed">
    <origin rpy="0 0 0" xyz="0 0.015 0"/>
    <parent link="d435i_camera_link"/>
    <child link="d435i_camera_color_frame"/>
  </joint>
  <link name="d435i_camera_color_frame"/>
  <joint name="d435i_camera_color_optical_joint" type="fixed">
    <origin rpy="-1.5707963267948966 0 -1.5707963267948966" xyz="0 0 0"/>
    <parent link="d435i_camera_color_frame"/>
    <child link="d435i_camera_color_optical_frame"/>
  </joint>
  <link name="d435i_camera_color_optical_frame"/>
  <link name="d435i_camera_accel_frame"/>
  <link name="d435i_camera_accel_optical_frame"/>
  <link name="d435i_camera_gyro_frame"/>
  <link name="d435i_camera_gyro_optical_frame"/>
  <joint name="d435i_camera_accel_joint" type="fixed">
    <origin rpy="0 0 0" xyz="-0.01174 -0.00552 0.0051"/>
    <parent link="d435i_camera_link"/>
    <child link="d435i_camera_accel_frame"/>
  </joint>
  <joint name="d435i_camera_accel_optical_joint" type="fixed">
    <origin rpy="-1.5707963267948966 0 -1.5707963267948966" xyz="0 0 0"/>
    <parent link="d435i_camera_accel_frame"/>
    <child link="d435i_camera_accel_optical_frame"/>
  </joint>
  <joint name="d435i_camera_gyro_joint" type="fixed">
    <origin rpy="0 0 0" xyz="-0.01174 -0.00552 0.0051"/>
    <parent link="d435i_camera_link"/>
    <child link="d435i_camera_gyro_frame"/>
  </joint>
  <joint name="d435i_camera_gyro_optical_joint" type="fixed">
    <origin rpy="-1.5707963267948966 0 -1.5707963267948966" xyz="0 0 0"/>
    <parent link="d435i_camera_gyro_frame"/>
    <child link="d435i_camera_gyro_optical_frame"/>
  </joint>
  <!-- Link for camera image and gazebe plugin-->
  <link name="camera_image_link">
    <inertial>
      <origin xyz="0 0 0"/>
      <mass value="0"/>
      <inertia ixx="0" ixy="0" ixz="0" iyy="0" iyz="0" izz="0"/>
    </inertial>
  </link>
  <joint name="camera_image_joint" type="fixed">
    <parent link="body"/>
    <child link="camera_image_link"/>
    <!-- <origin rpy="0 0 0" xyz="${d435_cam_x} ${d435_cam_y} ${d435_cam_z}" /> -->
    <origin rpy="-1.5707963267948966 0 0" xyz="0.290755 5.3e-05 0.068583"/>
  </joint>
  <link name="laser_frame"/>
  <joint name="laser_joint" type="fixed">
    <parent link="camera_image_link"/>
    <child link="laser_frame"/>
    <origin rpy="1.5707963267948966 0 0" xyz="0 0 0"/>
  </joint>
  <!-- <gazebo reference="camera_image_link"> -->
  <gazebo reference="camera_image_link">
    <self_collide>0</self_collide>
    <enable_wind>0</enable_wind>
    <kinematic>0</kinematic>
    <gravity>1</gravity>
    <!--<mu>1</mu>-->
    <mu2>1</mu2>
    <fdir1>0 0 0</fdir1>
    <!--<slip1>0</slip1>
            <slip2>0</slip2>-->
    <kp>1e+13</kp>
    <kd>1</kd>
    <!--<max_vel>0.01</max_vel>
            <min_depth>0</min_depth>-->
    <sensor name="d435i_cameracolor" type="camera">
      <camera name="d435i_camera">
        <horizontal_fov>1.2112585008840648</horizontal_fov>
        <image>
          <!-- <width>1280</width>
                        <height>720</height> -->
          <width>640</width>
          <height>480</height>
          <format>RGB_INT8</format>
        </image>
        <clip>
          <near>0.1</near>
          <far>100</far>
        </clip>
        <noise>
          <type>gaussian</type>
          <mean>0.0</mean>
          <stddev>0.007</stddev>
        </noise>
      </camera>
      <always_on>1</always_on>
      <update_rate>60</update_rate>
      <visualize>1</visualize>
    </sensor>
    <sensor name="d435i_cameraired1" type="camera">
      <camera name="d435i_camera">
        <horizontal_fov>1.4870205226991688</horizontal_fov>
        <image>
          <width>640</width>
          <height>480</height>
          <format>L_INT8</format>
        </image>
        <clip>
          <near>0.1</near>
          <far>100</far>
        </clip>
        <noise>
          <type>gaussian</type>
          <mean>0.0</mean>
          <stddev>0.05</stddev>
        </noise>
      </camera>
      <always_on>1</always_on>
      <update_rate>0</update_rate>
      <visualize>0</visualize>
    </sensor>
    <sensor name="d435i_cameraired2" type="camera">
      <camera name="d435i_camera">
        <horizontal_fov>1.4870205226991688</horizontal_fov>
        <image>
          <width>640</width>
          <height>480</height>
          <format>L_INT8</format>
        </image>
        <clip>
          <near>0.1</near>
          <far>100</far>
        </clip>
        <noise>
          <type>gaussian</type>
          <mean>0.0</mean>
          <stddev>0.05</stddev>
        </noise>
      </camera>
      <always_on>1</always_on>
      <update_rate>0</update_rate>
      <visualize>0</visualize>
    </sensor>
    <sensor name="d435i_cameradepth" type="depth">
      <camera name="d435i_camera">
        <horizontal_fov>1.4870205226991688</horizontal_fov>
        <image>
          <!-- <width>1280</width>
                        <height>720</height> -->
          <width>640</width>
          <height>480</height>
        </image>
        <clip>
          <near>0.1</near>
          <far>100</far>
        </clip>
        <noise>
          <type>gaussian</type>
          <mean>0.0</mean>
          <stddev>0.100</stddev>
        </noise>
      </camera>
      <always_on>1</always_on>
      <update_rate>90</update_rate>
      <visualize>0</visualize>
    </sensor>
  </gazebo>
  <gazebo>
    <plugin filename="librealsense_gazebo_plugin.so" name="/d435i_camera">
      <prefix>d435i_camera</prefix>
      <depthUpdateRate>90.0</depthUpdateRate>
      <colorUpdateRate>60.0</colorUpdateRate>
      <infraredUpdateRate>0.0</infraredUpdateRate>
      <depthTopicName>/d435i_camera/depth/image_rect_raw</depthTopicName>
      <depthCameraInfoTopicName>/d435i_camera/depth/camera_info</depthCameraInfoTopicName>
      <colorTopicName>/d435i_camera/color/image_raw</colorTopicName>
      <colorCameraInfoTopicName>/d435i_camera/color/camera_info</colorCameraInfoTopicName>
      <infrared1TopicName>/d435i_camera/infra1/image_raw</infrared1TopicName>
      <infrared1CameraInfoTopicName>/d435i_camera/infra1/camera_info</infrared1CameraInfoTopicName>
      <infrared2TopicName>/d435i_camera/infra2/image_raw</infrared2TopicName>
      <infrared2CameraInfoTopicName>/d435i_camera/infra2/camera_info</infrared2CameraInfoTopicName>
      <colorOpticalframeName>d435i_camera_color_optical_frame</colorOpticalframeName>
      <depthOpticalframeName>d435i_camera_depth_optical_frame</depthOpticalframeName>
      <infrared1OpticalframeName>d435i_camera_infra1_frame</infrared1OpticalframeName>
      <infrared2OpticalframeName>d435i_camera_infra2_frame</infrared2OpticalframeName>
      <rangeMinDepth>0.2</rangeMinDepth>
      <rangeMaxDepth>10.0</rangeMaxDepth>
      <pointCloud>False</pointCloud>
      <pointCloudTopicName>/d435i_camera/depth/color/points</pointCloudTopicName>
      <pointCloudCutoff>0.25</pointCloudCutoff>
      <pointCloudCutoffMax>9.0</pointCloudCutoffMax>
    </plugin>
  </gazebo>
  <!-- Adjust color for gazebo-->
  <gazebo reference="d435i_camera_link">
    <material>Gazebo/Grey</material>
  </gazebo>
  <link name="imu_link">
    <inertial>
      <origin rpy="0 0 0" xyz="0 0 0"/>
      <mass value="0.0"/>
      <inertia ixx="0" ixy="0" ixz="0" iyy="0" iyz="0" izz="0"/>
    </inertial>
    <visual>
      <origin rpy="0 0 0" xyz="0 0 0"/>
      <geometry>
        <box size="0.01 0.01 0.01"/>
      </geometry>
      <material name="red"/>
    </visual>
  </link>
  <joint name="imu_joint" type="fixed">
    <parent link="body"/>
    <child link="imu_link"/>
  </joint>
  <!-- LEGS LINKS 0-4  -->
  <link name="fr_l0">
    <!-- <inertial>
      <origin rpy="0 0 0" xyz="0.0557 0.016 0"/>
      <mass value="0.645"/>
      <inertia ixx="0.0052" ixy="0" ixz="0" iyy="0.0093" iyz="0" izz="0.0065"/>
    </inertial> -->
    <inertial>
      <origin xyz="50.33286050e-3 11.96674461e-3 0.45712186e-3"/>
      <mass value="0.64500000"/>
      <inertia ixx="498.32637726e-6" ixy="-43.44106123e-6" ixz="-0.22311702e-6" iyy="842.25430777e-6" iyz="-0.01118942e-6" izz="586.98453014e-6"/>
    </inertial>
    <visual>
      <origin rpy="0 0 0" xyz="0 0 0"/>
      <geometry>
        <mesh filename="file:///home/junninghuang/ros2_ws/install/mab_description/share/mab_description/meshes/hb40/l0r.stl" scale="0.001 0.001 0.001"/>
      </geometry>
      <material name="silver"/>
    </visual>
  </link>
  <link name="fr_l1">
    <!-- <inertial>
      <origin rpy="0 0 0" xyz="0.031 -0.0164 -0.003"/>
      <mass value="0.827"/>
      <inertia ixx="0.0330" ixy="0" ixz="0" iyy="0.0077" iyz="0" izz="0.0286"/>
    </inertial> -->
    <inertial>
      <origin xyz="41.97647538e-3 -50.28912232e-3 5.24458524e-3"/>
      <mass value="0.82700000"/>
      <inertia ixx="4027.34053636e-6" ixy="339.60345125e-6" ixz="-19.19423339e-6" iyy="719.63841788e-6" iyz="70.69913102e-6" izz="3870.59006761e-6"/>
    </inertial>
    <visual>
      <origin rpy="0 0 0" xyz="0 0 0"/>
      <geometry>
        <mesh filename="file:///home/junninghuang/ros2_ws/install/mab_description/share/mab_description/meshes/hb40/l1r.stl" scale="0.001 0.001 0.001"/>
      </geometry>
      <material name="orange"/>
    </visual>
    <collision>
      <origin rpy="0 1.57 0" xyz="0.0 0 0"/>
      <geometry>
        <cylinder length="0.11" radius="0.05"/>
      </geometry>
      <material name="invisible"/>
    </collision>
  </link>
  <link name="fr_l2">
    <!-- <inertial>
      <origin rpy="0 0 0" xyz="0.001 -0.104 -0.003"/>
      <mass value="0.118"/>
      <inertia ixx="0.0213" ixy="0" ixz="0" iyy="0.0002" iyz="0" izz="0.0212"/>
    </inertial> -->
    <inertial>
      <origin xyz="1.42261228e-3 -96.66711845e-3 1.53962525e-3"/>
      <mass value="0.11800000"/>
      <inertia ixx="524.76797677e-6" ixy="16.28790079e-6" ixz="0.26927944e-6" iyy="22.71638836e-6" iyz="-9.50678837e-6" izz="518.76368169e-6"/>
    </inertial>
    <visual>
      <origin rpy="0 0 0" xyz="0 0 0"/>
      <geometry>
        <mesh filename="file:///home/junninghuang/ros2_ws/install/mab_description/share/mab_description/meshes/hb40/l2r.stl" scale="0.001 0.001 0.001"/>
      </geometry>
      <material name="red"/>
    </visual>
    <collision>
      <origin rpy="1.3 0 0" xyz="0 0.01 0.0055"/>
      <geometry>
        <cylinder length="0.0625" radius="0.01"/>
      </geometry>
      <material name="invisible"/>
    </collision>
    <collision>
      <origin rpy="1.67 0.0 0.05" xyz="0 -0.1 0.005"/>
      <geometry>
        <cylinder length="0.2" radius="0.015"/>
      </geometry>
      <material name="invisible"/>
    </collision>
  </link>
  <link name="fr_foot">
    <inertial>
      <origin rpy="0 0 0" xyz="0.0 0.0 0.0"/>
      <mass value="0.0"/>
      <inertia ixx="0.0" ixy="0" ixz="0" iyy="0.0" iyz="0" izz="0.0"/>
    </inertial>
    <visual>
      <origin rpy="0 0 0" xyz="0 0 0"/>
      <geometry>
        <sphere radius="0.021"/>
      </geometry>
      <material name="black"/>
    </visual>
    <collision>
      <origin rpy="0 0 0" xyz="0 0 0"/>
      <geometry>
        <sphere radius="0.02"/>
      </geometry>
    </collision>
  </link>
  <link name="fl_l0">
    <!-- <inertial>
      <origin rpy="0 0 0" xyz="0.0557 -0.016 0"/>
      <mass value="0.645"/>
      <inertia ixx="0.0052" ixy="0" ixz="0" iyy="0.0093" iyz="0" izz="0.0065"/>
    </inertial> -->
    <inertial>
      <origin xyz="50.33286050e-3 -11.96674465e-3 -0.45712069e-3"/>
      <mass value="0.64500000"/>
      <inertia ixx="498.32637694e-6" ixy="43.44106109e-6" ixz="0.22310959e-6" iyy="842.25430695e-6" iyz="-0.01120420e-6" izz="586.98452955e-6"/>
    </inertial>
    <visual>
      <origin rpy="0 0 0" xyz="0 0 0"/>
      <geometry>
        <mesh filename="file:///home/junninghuang/ros2_ws/install/mab_description/share/mab_description/meshes/hb40/l0l.stl" scale="0.001 0.001 0.001"/>
      </geometry>
      <material name="silver"/>
    </visual>
  </link>
  <link name="fl_l1">
    <!-- <inertial>
      <origin rpy="0 0 0" xyz="0.031 0.0164 -0.003"/>
      <mass value="0.827"/>
      <inertia ixx="0.0330" ixy="0" ixz="0" iyy="0.0077" iyz="0" izz="0.0286"/>
    </inertial> -->
    <inertial>
      <origin xyz="41.97647986e-3 50.28911905e-3 5.24459395e-3"/>
      <mass value="0.82700000"/>
      <inertia ixx="4027.34061087e-6" ixy="-339.60373031e-6" ixz="-19.19430819e-6" iyy="719.63850817e-6" iyz="-70.69968381e-6" izz="3870.59018254e-6"/>
    </inertial>
    <visual>
      <origin rpy="0 0 0" xyz="0 0 0"/>
      <geometry>
        <mesh filename="file:///home/junninghuang/ros2_ws/install/mab_description/share/mab_description/meshes/hb40/l1lf.stl" scale="0.001 0.001 0.001"/>
      </geometry>
      <material name="orange"/>
    </visual>
    <collision>
      <origin rpy="0 1.57 0" xyz="0.0 0 0"/>
      <geometry>
        <cylinder length="0.11" radius="0.05"/>
      </geometry>
      <material name="invisible"/>
    </collision>
  </link>
  <link name="fl_l2">
    <!-- <inertial>
      <origin rpy="0 0 0" xyz="0.001 0.104 -0.003"/>
      <mass value="0.118"/>
      <inertia ixx="0.0213" ixy="0" ixz="0" iyy="0.0002" iyz="0" izz="0.0212"/>
    </inertial> -->
    <inertial>
      <origin xyz="1.42261242e-3 96.66711821e-3 1.53963358e-3"/>
      <mass value="0.11800000"/>
      <inertia ixx="524.76797815e-6" ixy="-16.28789980e-6" ixz="0.26927746e-6" iyy="22.71638636e-6" iyz="9.50674532e-6" izz="518.76368492e-6"/>
    </inertial>
    <visual>
      <origin rpy="0 0 0" xyz="0 0 0"/>
      <geometry>
        <mesh filename="file:///home/junninghuang/ros2_ws/install/mab_description/share/mab_description/meshes/hb40/l2l.stl" scale="0.001 0.001 0.001"/>
      </geometry>
      <material name="silver"/>
    </visual>
    <collision>
      <origin rpy="-1.3 0.0 -0.00" xyz="0 -0.01 0.0055"/>
      <geometry>
        <cylinder length="0.0625" radius="0.01"/>
      </geometry>
      <material name="invisible"/>
    </collision>
    <collision>
      <origin rpy="-1.67 0.0 -0.05" xyz="0 0.1 0.005"/>
      <geometry>
        <cylinder length="0.2" radius="0.015"/>
      </geometry>
      <material name="invisible"/>
    </collision>
  </link>
  <link name="fl_foot">
    <inertial>
      <origin rpy="0 0 0" xyz="0.0 0.0 0.0"/>
      <mass value="0.0"/>
      <inertia ixx="0.0" ixy="0" ixz="0" iyy="0.0" iyz="0" izz="0.0"/>
    </inertial>
    <visual>
      <origin rpy="0 0 0" xyz="0 0 0"/>
      <geometry>
        <sphere radius="0.021"/>
      </geometry>
      <material name="black"/>
    </visual>
    <collision>
      <origin rpy="0 0 0" xyz="0 0 0"/>
      <geometry>
        <sphere radius="0.02"/>
      </geometry>
    </collision>
  </link>
  <link name="rl_l0">
    <!-- <inertial>
      <origin rpy="0 0 0" xyz="0.0557 0.016 0"/>
      <mass value="0.645"/>
      <inertia ixx="0.0052" ixy="0" ixz="0" iyy="0.0093" iyz="0" izz="0.0065"/>
    </inertial> -->
    <inertial>
      <origin xyz="50.33286050e-3 -11.96674465e-3 -0.45712069e-3"/>
      <mass value="0.64500000"/>
      <inertia ixx="498.32637694e-6" ixy="43.44106109e-6" ixz="0.22310959e-6" iyy="842.25430695e-6" iyz="-0.01120420e-6" izz="586.98452955e-6"/>
    </inertial>
    <visual>
      <origin rpy="0 0 0" xyz="0 0 0"/>
      <geometry>
        <mesh filename="file:///home/junninghuang/ros2_ws/install/mab_description/share/mab_description/meshes/hb40/l0r.stl" scale="0.001 0.001 0.001"/>
      </geometry>
      <material name="silver"/>
    </visual>
  </link>
  <link name="rl_l1">
    <!-- <inertial>
      <origin rpy="0 0 0" xyz="0.031 0.0164 -0.003"/>
      <mass value="0.827"/>
      <inertia ixx="0.0330" ixy="0" ixz="0" iyy="0.0077" iyz="0" izz="0.0286"/>
    </inertial> -->
    <inertial>
      <origin xyz="41.97647986e-3 50.28911905e-3 5.24459395e-3"/>
      <mass value="0.82700000"/>
      <inertia ixx="4027.34061087e-6" ixy="-339.60373031e-6" ixz="-19.19430819e-6" iyy="719.63850817e-6" iyz="-70.69968381e-6" izz="3870.59018254e-6"/>
    </inertial>
    <visual>
      <origin rpy="0 0 0" xyz="0 0 0"/>
      <geometry>
        <mesh filename="file:///home/junninghuang/ros2_ws/install/mab_description/share/mab_description/meshes/hb40/l1lf.stl" scale="0.001 0.001 0.001"/>
      </geometry>
      <material name="orange"/>
    </visual>
    <collision>
      <origin rpy="0 1.57 0" xyz="0.0 0 0"/>
      <geometry>
        <cylinder length="0.11" radius="0.05"/>
        <material name="invisible"/>
      </geometry>
    </collision>
  </link>
  <link name="rl_l2">
    <!-- <inertial>
      <origin rpy="0 0 0" xyz="0.001 0.104 -0.003"/>
      <mass value="0.118"/>
      <inertia ixx="0.0213" ixy="0" ixz="0" iyy="0.0002" iyz="0" izz="0.0212"/>
    </inertial> -->
    <inertial>
      <origin xyz="1.42261242e-3 96.66711821e-3 1.53963358e-3"/>
      <mass value="0.11800000"/>
      <inertia ixx="524.76797815e-6" ixy="-16.28789980e-6" ixz="0.26927746e-6" iyy="22.71638636e-6" iyz="9.50674532e-6" izz="518.76368492e-6"/>
    </inertial>
    <visual>
      <origin rpy="0 0 0" xyz="0 0 0"/>
      <geometry>
        <mesh filename="file:///home/junninghuang/ros2_ws/install/mab_description/share/mab_description/meshes/hb40/l2l.stl" scale="0.001 0.001 0.001"/>
      </geometry>
      <material name="silver"/>
    </visual>
    <collision>
      <origin rpy="-1.3 0 0" xyz="0 -0.01 0.0055"/>
      <geometry>
        <cylinder length="0.0625" radius="0.01"/>
      </geometry>
      <material name="invisible"/>
    </collision>
    <collision>
      <origin rpy="-1.67 0.0 -0.05" xyz="0 0.1 0.005"/>
      <geometry>
        <cylinder length="0.2" radius="0.015"/>
        <material name="invisible"/>
      </geometry>
    </collision>
  </link>
  <link name="rl_foot">
    <inertial>
      <origin rpy="0 0 0" xyz="0.0 0.0 0.0"/>
      <mass value="0.0"/>
      <inertia ixx="0.0" ixy="0" ixz="0" iyy="0.0" iyz="0" izz="0.0"/>
    </inertial>
    <visual>
      <origin rpy="0 0 0" xyz="0 0 0"/>
      <geometry>
        <sphere radius="0.021"/>
      </geometry>
      <material name="black"/>
    </visual>
    <collision>
      <origin rpy="0 0 0" xyz="0 0 0"/>
      <geometry>
        <sphere radius="0.02"/>
      </geometry>
    </collision>
  </link>
  <link name="rr_l0">
    <!-- <inertial>
      <origin rpy="0 0 0" xyz="0.0557 -0.016 0"/>
      <mass value="0.645"/>
      <inertia ixx="0.0052" ixy="0" ixz="0" iyy="0.0093" iyz="0" izz="0.0065"/>
    </inertial> -->
    <inertial>
      <origin xyz="50.33286050e-3 11.96674461e-3 0.45712186e-3"/>
      <mass value="0.64500000"/>
      <inertia ixx="498.32637726e-6" ixy="-43.44106123e-6" ixz="-0.22311702e-6" iyy="842.25430777e-6" iyz="-0.01118942e-6" izz="586.98453014e-6"/>
    </inertial>
    <visual>
      <origin rpy="0 0 0" xyz="0 0 0"/>
      <geometry>
        <mesh filename="file:///home/junninghuang/ros2_ws/install/mab_description/share/mab_description/meshes/hb40/l0l.stl" scale="0.001 0.001 0.001"/>
      </geometry>
      <material name="silver"/>
    </visual>
  </link>
  <link name="rr_l1">
    <!-- <inertial>
      <origin rpy="0 0 0" xyz="0.031 -0.0164 -0.003"/>
      <mass value="0.827"/>
      <inertia ixx="0.0330" ixy="0" ixz="0" iyy="0.0077" iyz="0" izz="0.0286"/>
    </inertial> -->
    <inertial>
      <origin xyz="41.97647538e-3 -50.28912232e-3 5.24458524e-3"/>
      <mass value="0.82700000"/>
      <inertia ixx="4027.34053636e-6" ixy="339.60345125e-6" ixz="-19.19423339e-6" iyy="719.63841788e-6" iyz="70.69913102e-6" izz="3870.59006761e-6"/>
    </inertial>
    <visual>
      <origin rpy="0 0 0" xyz="0 0 0"/>
      <geometry>
        <mesh filename="file:///home/junninghuang/ros2_ws/install/mab_description/share/mab_description/meshes/hb40/l1r.stl" scale="0.001 0.001 0.001"/>
      </geometry>
      <material name="orange"/>
    </visual>
    <collision>
      <origin rpy="0 1.57 0" xyz="0.0 0 0"/>
      <geometry>
        <cylinder length="0.11" radius="0.05"/>
        <material name="invisible"/>
      </geometry>
    </collision>
  </link>
  <link name="rr_l2">
    <!-- <inertial>
      <origin rpy="0 0 0" xyz="0.001 -0.104 -0.003"/>
      <mass value="0.118"/>
      <inertia ixx="0.0213" ixy="0" ixz="0" iyy="0.0002" iyz="0" izz="0.0212"/>
    </inertial> -->
    <inertial>
      <origin xyz="1.42261228e-3 -96.66711845e-3 1.53962525e-3"/>
      <mass value="0.11800000"/>
      <inertia ixx="524.76797677e-6" ixy="16.28790079e-6" ixz="0.26927944e-6" iyy="22.71638836e-6" iyz="-9.50678837e-6" izz="518.76368169e-6"/>
    </inertial>
    <visual>
      <origin rpy="0 0 0" xyz="0 0 0"/>
      <geometry>
        <mesh filename="file:///home/junninghuang/ros2_ws/install/mab_description/share/mab_description/meshes/hb40/l2r.stl" scale="0.001 0.001 0.001"/>
      </geometry>
      <material name="silver"/>
    </visual>
    <collision>
      <origin rpy="1.3 0.0 0" xyz="0 0.01 0.0055"/>
      <geometry>
        <cylinder length="0.0625" radius="0.01"/>
        <material name="invisible"/>
      </geometry>
    </collision>
    <collision>
      <origin rpy="1.67 0.0 0.05" xyz="0 -0.1 0.005"/>
      <geometry>
        <cylinder length="0.2" radius="0.015"/>
        <material name="invisible"/>
      </geometry>
    </collision>
  </link>
  <link name="rr_foot">
    <inertial>
      <origin rpy="0 0 0" xyz="0.0 0.0 0.0"/>
      <mass value="0.0"/>
      <inertia ixx="0.0" ixy="0" ixz="0" iyy="0.0" iyz="0" izz="0.0"/>
    </inertial>
    <visual>
      <origin rpy="0 0 0" xyz="0 0 0"/>
      <geometry>
        <sphere radius="0.021"/>
      </geometry>
      <material name="black"/>
    </visual>
    <collision>
      <origin rpy="0 0 0" xyz="0 0 0"/>
      <geometry>
        <sphere radius="0.02"/>
      </geometry>
    </collision>
  </link>
  <!-- LEGS JOINTS 0-4  -->
  <!-- Front Right Leg -->
  <joint armature="0.01" name="fr_j0" type="revolute">
    <parent link="body"/>
    <child link="fr_l0"/>
    <origin rpy="0 0 0" xyz="0.1375 -0.064 0"/>
    <axis xyz="1.0 0 0"/>
    <limit effort="16" lower="-1.57" upper="1.57" velocity="25"/>
  </joint>
  <joint name="fr_j1" type="revolute">
    <parent link="fr_l0"/>
    <child link="fr_l1"/>
    <origin rpy="0 0 -1.57" xyz="0.0555 -0.0125 0"/>
    <axis xyz="1.0 0 0"/>
    <limit effort="16" lower="-1.57" upper="1.57" velocity="25"/>
  </joint>
  <joint name="fr_j2" type="revolute">
    <parent link="fr_l1"/>
    <child link="fr_l2"/>
    <origin rpy="2.909 0 0" xyz="0.0584 -0.200 0"/>
    <axis xyz="1.0 0 0"/>
    <limit effort="16" lower="-2.53" upper="0.0" velocity="25"/>
  </joint>
  <joint name="fr_jFoot" type="fixed">
    <parent link="fr_l2"/>
    <child link="fr_foot"/>
    <origin rpy="0 0 0" xyz="0.0054 -0.200 0"/>
    <axis xyz="0.0 0 0"/>
  </joint>
  <!-- Front Left Leg -->
  <joint armature="0.01" name="fl_j0" type="revolute">
    <parent link="body"/>
    <child link="fl_l0"/>
    <origin rpy="0 0 0" xyz="0.137 0.064 0"/>
    <axis xyz="1.0 0 0"/>
    <limit effort="16" lower="-1.57" upper="1.57" velocity="25"/>
  </joint>
  <joint name="fl_j1" type="revolute">
    <parent link="fl_l0"/>
    <child link="fl_l1"/>
    <origin rpy="0 0 1.57" xyz="0.0555 0.0125 0"/>
    <axis xyz="1.0 0 0"/>
    <limit effort="16" lower="-1.57" upper="1.57" velocity="25"/>
  </joint>
  <joint name="fl_j2" type="revolute">
    <parent link="fl_l1"/>
    <child link="fl_l2"/>
    <origin rpy="-2.909 0 0" xyz="0.0584 0.200 0"/>
    <axis xyz="1.0 0 0"/>
    <limit effort="16" lower="0.0" upper="2.53" velocity="25"/>
  </joint>
  <joint name="fl_jFoot" type="fixed">
    <parent link="fl_l2"/>
    <child link="fl_foot"/>
    <origin rpy="0 0 0" xyz="0.0054 0.200 0"/>
    <axis xyz="0.0 0 0"/>
  </joint>
  <!-- Rear Left Leg -->
  <joint armature="0.01" name="rl_j0" type="revolute">
    <parent link="body"/>
    <child link="rl_l0"/>
    <origin rpy="0 0 -3.14159" xyz="-0.1375 0.064 0"/>
    <axis xyz="1.0 0 0"/>
    <limit effort="16" lower="-1.57" upper="1.57" velocity="25"/>
  </joint>
  <joint name="rl_j1" type="revolute">
    <parent link="rl_l0"/>
    <child link="rl_l1"/>
    <origin rpy="0 0 -1.57" xyz="0.0555 -0.0125 0"/>
    <axis xyz="1.0 0 0"/>
    <limit effort="16" lower="-1.57" upper="1.57" velocity="25"/>
  </joint>
  <joint name="rl_j2" type="revolute">
    <parent link="rl_l1"/>
    <child link="rl_l2"/>
    <origin rpy="-2.909 0 0" xyz="0.0584 0.20 0"/>
    <axis xyz="1.0 0 0"/>
    <limit effort="16" lower="0.0" upper="2.53" velocity="25"/>
  </joint>
  <joint name="rl_jFoot" type="fixed">
    <parent link="rl_l2"/>
    <child link="rl_foot"/>
    <origin rpy="0 0 0" xyz="0.0054 0.200 0"/>
    <axis xyz="0.0 0 0"/>
  </joint>
  <!-- Rear Right Leg -->
  <joint armature="0.01" name="rr_j0" type="revolute">
    <parent link="body"/>
    <child link="rr_l0"/>
    <origin rpy="0 0 -3.14159" xyz="-0.1375 -0.064 0"/>
    <axis xyz="1.0 0 0"/>
    <limit effort="16" lower="-1.57" upper="1.57" velocity="25"/>
  </joint>
  <joint name="rr_j1" type="revolute">
    <parent link="rr_l0"/>
    <child link="rr_l1"/>
    <origin rpy="0 0 1.57" xyz="0.0555 0.0125 0"/>
    <axis xyz="1.0 0 0"/>
    <limit effort="16" lower="-1.57" upper="1.57" velocity="25"/>
  </joint>
  <joint name="rr_j2" type="revolute">
    <parent link="rr_l1"/>
    <child link="rr_l2"/>
    <origin rpy="2.909 0 0" xyz="0.0584 -0.20 0"/>
    <axis xyz="1.0 0 0"/>
    <limit effort="16" lower="-2.53" upper="0.0" velocity="25"/>
  </joint>
  <joint name="rr_jFoot" type="fixed">
    <parent link="rr_l2"/>
    <child link="rr_foot"/>
    <origin rpy="0 0 0" xyz="0.0054 -0.200 0"/>
    <axis xyz="0.0 0 0"/>
  </joint>
</robot>
