<?xml version="1.0" ?>
<!-- =================================================================================== -->
<!-- |    This document was autogenerated by xacro from src/mab_ros/mab_description/xacro/silver_badger.urdf.xacro | -->
<!-- |    EDITING THIS FILE BY HAND IS NOT RECOMMENDED                                 | -->
<!-- =================================================================================== -->
<robot name="silver_badger">
  <mujoco>
    <compiler balanceinertia="false" discardvisual="false"/>
  </mujoco>
  <physics type="ode">
    <max_step_size>0.001</max_step_size>
    <real_time_factor>1</real_time_factor>
    <real_time_update_rate>1000</real_time_update_rate>
    <ode>
      <solver>
        <type>quick</type>
        <iters>300</iters>
        <sor>1.3</sor>
      </solver>
      <constraints>
        <cfm>0.00001</cfm>
        <erp>0.2</erp>
        <contact_max_correcting_vel>10.0</contact_max_correcting_vel>
        <contact_surface_layer>0.001</contact_surface_layer>
      </constraints>
    </ode>
  </physics>
  <!-- Colors-->
  <gazebo reference="body">
    <mu1>0.2</mu1>
    <mu2>0.2</mu2>
    <material>Gazebo/Grey</material>
  </gazebo>
  <gazebo reference="rear">
    <mu1>0.2</mu1>
    <mu2>0.2</mu2>
    <material>Gazebo/Grey</material>
  </gazebo>
  <gazebo reference="fr_l0">
    <mu1>0.2</mu1>
    <mu2>0.2</mu2>
    <material>Gazebo/Grey</material>
  </gazebo>
  <gazebo reference="fr_l1">
    <mu1>0.2</mu1>
    <mu2>0.2</mu2>
    <material>Gazebo/Orange</material>
  </gazebo>
  <gazebo reference="fr_l2">
    <mu1>0.2</mu1>
    <mu2>0.2</mu2>
    <material>Gazebo/Grey</material>
  </gazebo>
  <gazebo reference="fr_foot">
    <mu1>0.6</mu1>
    <mu2>0.6</mu2>
    <self_collide>0</self_collide>
    <kp value="1e15"/>
    <kd value="1e13"/>
    <material>Gazebo/Black</material>
  </gazebo>
  <gazebo reference="fl_l0">
    <mu1>0.2</mu1>
    <mu2>0.2</mu2>
    <material>Gazebo/Grey</material>
  </gazebo>
  <gazebo reference="fl_l1">
    <mu1>0.2</mu1>
    <mu2>0.2</mu2>
    <material>Gazebo/Orange</material>
  </gazebo>
  <gazebo reference="fl_l2">
    <mu1>0.2</mu1>
    <mu2>0.2</mu2>
    <material>Gazebo/Grey</material>
  </gazebo>
  <gazebo reference="fl_foot">
    <mu1>0.6</mu1>
    <mu2>0.6</mu2>
    <self_collide>0</self_collide>
    <kp value="1e15"/>
    <kd value="1e13"/>
    <material>Gazebo/Black</material>
  </gazebo>
  <gazebo reference="rl_l0">
    <mu1>0.2</mu1>
    <mu2>0.2</mu2>
    <material>Gazebo/Grey</material>
  </gazebo>
  <gazebo reference="rl_l1">
    <mu1>0.2</mu1>
    <mu2>0.2</mu2>
    <material>Gazebo/Orange</material>
  </gazebo>
  <gazebo reference="rl_l2">
    <mu1>0.2</mu1>
    <mu2>0.2</mu2>
    <material>Gazebo/Grey</material>
  </gazebo>
  <gazebo reference="rl_foot">
    <mu1>0.6</mu1>
    <mu2>0.6</mu2>
    <self_collide>0</self_collide>
    <kp value="1e15"/>
    <kd value="1e13"/>
    <material>Gazebo/Black</material>
  </gazebo>
  <gazebo reference="rr_l0">
    <mu1>0.2</mu1>
    <mu2>0.2</mu2>
    <material>Gazebo/Grey</material>
  </gazebo>
  <gazebo reference="rr_l1">
    <mu1>0.2</mu1>
    <mu2>0.2</mu2>
    <material>Gazebo/Orange</material>
  </gazebo>
  <gazebo reference="rr_l2">
    <mu1>0.2</mu1>
    <mu2>0.2</mu2>
    <material>Gazebo/Grey</material>
  </gazebo>
  <gazebo reference="rr_foot">
    <mu1>0.6</mu1>
    <mu2>0.6</mu2>
    <self_collide>0</self_collide>
    <kp value="1e15"/>
    <kd value="1e13"/>
    <material>Gazebo/Black</material>
  </gazebo>
  <gazebo reference="camera_mount">
    <material>Gazebo/DarkGrey</material>
  </gazebo>
  <gazebo reference="camera_interface">
    <material>Gazebo/DarkGrey</material>
  </gazebo>
  <!-- Controllers-->
  <!-- <gazebo>
      <plugin name="gazebo_ros2_control" filename="libgazebo_ros2_control.so">
        <parameters>$(find mab_gazebo)/config/silver_badger_controller.yaml</parameters>
      </plugin>
    </gazebo> -->
  <gazebo>
    <plugin filename="libmab_control.so" name="mab_gazebo_plugin">
      <robot>silver_badger</robot>
    </plugin>
  </gazebo>
  <gazebo reference="imu_link">
    <!-- <gazebo reference="d435i_camera_accel_frame"> -->
    <gravity>true</gravity>
    <sensor name="imu_sensor" type="imu">
      <always_on>1</always_on>
      <update_rate>500</update_rate>
      <visualize>1</visualize>
      <topic>imu</topic>
      <plugin filename="libgazebo_ros_imu_sensor.so" name="imu">
        <topicName>imu</topicName>
        <bodyName>imu_sensor_link</bodyName>
        <updateRateHZ>100.0</updateRateHZ>
        <xyzOffset>0 0 0</xyzOffset>
        <rpyOffset>0 0 0</rpyOffset>
        <gaussianNoise>0.0</gaussianNoise>
        <!-- <gaussianNoise>0.017</gaussianNoise> -->
      </plugin>
      <pose>0 0 0 0 0 0</pose>
    </sensor>
  </gazebo>
  <!-- <gazebo reference="d435i_camera_accel_frame">
      <gravity>true</gravity>
      <sensor name='cam_imu_sensor' type='imu'>
          <always_on>1</always_on>
          <update_rate>100</update_rate>
          <visualize>1</visualize>
          <topic>cam_imu</topic>
          <plugin name='cam_imu' filename='libgazebo_ros_imu_sensor.so'>
              <topicName>cam_imu</topicName>
              <bodyName>cam_imu_sensor_link</bodyName>
              <updateRateHZ>100.0</updateRateHZ>
              <xyzOffset>0 0 0</xyzOffset>
              <rpyOffset>0 0 0</rpyOffset>
          </plugin>
          <pose>0 0 0 0 0 0</pose>
      </sensor>
    </gazebo> -->
  <!-- Foot Contact Sensors-->
  <gazebo reference="fr_foot">
    <sensor name="fr_foot_bumper" type="contact">
      <selfCollide>true</selfCollide>
      <alwaysOn>true</alwaysOn>
      <updateRate>50.0</updateRate>
      <material>Gazebo/Red</material>
      <contact>
        <collision>fr_l2_fixed_joint_lump__fr_foot_collision_2</collision>
      </contact>
      <plugin filename="libgazebo_ros_bumper.so" name="gazebo_ros_bumper_controller_fr_foot">
        <ros>
          <remapping>bumper_states:=feet_contact</remapping>
        </ros>
      </plugin>
    </sensor>
  </gazebo>
  <gazebo reference="fl_foot">
    <sensor name="fl_foot_bumper" type="contact">
      <selfCollide>true</selfCollide>
      <alwaysOn>true</alwaysOn>
      <updateRate>50.0</updateRate>
      <material>Gazebo/Red</material>
      <contact>
        <collision>fl_l2_fixed_joint_lump__fl_foot_collision_2</collision>
      </contact>
      <plugin filename="libgazebo_ros_bumper.so" name="gazebo_ros_bumper_controller_fl_foot">
        <ros>
          <remapping>bumper_states:=feet_contact</remapping>
        </ros>
      </plugin>
    </sensor>
  </gazebo>
  <gazebo reference="rr_foot">
    <sensor name="rr_foot_bumper" type="contact">
      <selfCollide>true</selfCollide>
      <alwaysOn>true</alwaysOn>
      <updateRate>50.0</updateRate>
      <material>Gazebo/Red</material>
      <contact>
        <collision>rr_l2_fixed_joint_lump__rr_foot_collision_2</collision>
      </contact>
      <plugin filename="libgazebo_ros_bumper.so" name="gazebo_ros_bumper_controller_rr_foot">
        <ros>
          <remapping>bumper_states:=feet_contact</remapping>
        </ros>
      </plugin>
    </sensor>
  </gazebo>
  <gazebo reference="rl_foot">
    <sensor name="rl_foot_bumper" type="contact">
      <selfCollide>true</selfCollide>
      <alwaysOn>true</alwaysOn>
      <updateRate>50.0</updateRate>
      <material>Gazebo/Red</material>
      <contact>
        <collision>rl_l2_fixed_joint_lump__rl_foot_collision_2</collision>
      </contact>
      <plugin filename="libgazebo_ros_bumper.so" name="gazebo_ros_bumper_controller_rl_foot">
        <ros>
          <remapping>bumper_states:=feet_contact</remapping>
        </ros>
      </plugin>
    </sensor>
  </gazebo>
  <!-- Ground truth odom-->
  <gazebo>
    <plugin filename="libgazebo_ros_p3d.so" name="gazebo_ros_p3d">
      <ros>
        <remapping>odom:=odom_gt</remapping>
      </ros>
      <body_name>base_link</body_name>
      <frame_name>world</frame_name>
      <update_rate>100</update_rate>
      <xyz_offset>0 0 0</xyz_offset>
      <rpy_offset>0 0 0</rpy_offset>
      <gaussian_noise>0.0</gaussian_noise>
    </plugin>
  </gazebo>
  <material name="silver">
    <color rgba="0.600 0.600 0.600 1.000"/>
  </material>
  <material name="black">
    <color rgba="0.1 0.1 0.1 1.000"/>
  </material>
  <material name="red">
    <color rgba="1.0 0 0 1.000"/>
  </material>
  <material name="orange">
    <color rgba="1.0 0.41 0 1.000"/>
  </material>
  <material name="invisible">
    <color rgba="0 0 0 0"/>
  </material>
  <!-- Import control tags-->
  <!-- <xacro:include filename="$(find mab_description)/xacro/control.xacro" /> -->
  <!-- Initialize controls-->
  <!-- <xacro:silver_badger_ros2_control/> -->
  <!-- Initialize camera-->
  <!-- <xacro:include filename="$(find mab_description)/xacro/camera.xacro"/> -->
  <!-- Include camera mount files-->
  <!-- <xacro:include filename="$(find mab_description)/xacro/camera_mount.xacro"/> -->
  <!-- BODY -->
  <link name="base_link"/>
  <link name="body">
    <!-- <inertial>
      <origin rpy="0 0 0" xyz="0 0 0"/>
      <mass value="5.423"/>
      <inertia ixx="0.1946" ixy="0" ixz="0" iyy="0.4899" iyz="0" izz="0.6228"/>
    </inertial> -->
    <inertial>
      <origin xyz="19.23637020e-3 0.65977049e-3 3.38565104e-3"/>
      <mass value="5.42300000"/>
      <inertia ixx="21646.56458935e-6" ixy="-46.55756531e-6" ixz="18.07857599e-6" iyy="40703.39489390e-6" iyz="-71.07150002e-6" izz="54721.98086004e-6"/>
    </inertial>
    <visual>
      <origin rpy="0 0 0" xyz="0 0 0"/>
      <geometry>
        <mesh filename="file:///home/ws/install/mab_description/share/mab_description/meshes/hb40/body.stl" scale="0.001 0.001 0.001"/>
      </geometry>
      <material name="silver"/>
    </visual>
    <collision>
      <origin rpy="0 0 0" xyz="0 0 0"/>
      <geometry>
        <box size="0.22 0.2 0.1"/>
        <material name="invisible"/>
      </geometry>
    </collision>
  </link>
  <link name="rear">
    <!-- <inertial>
      <origin rpy="0 0 0" xyz="-0.038 0.075 0"/>
      <mass value="1.337"/>
      <inertia ixx="0.09" ixy="0" ixz="0" iyy="0.0835" iyz="0" izz="0.1561"/>
    </inertial> -->
    <inertial>
      <origin xyz="-38.28391582e-3 65.76740154e-3 0.15093929e-3"/>
      <mass value="1.33700000"/>
      <inertia ixx="1982.84311251e-6" ixy="-36.51038588e-6" ixz="-4.15042187e-6" iyy="4644.92962873e-6" iyz="0.10412770e-6" izz="5097.13064643e-6"/>
    </inertial>
    <visual>
      <origin rpy="0 0 0" xyz="0 0 0"/>
      <geometry>
        <mesh filename="file:///home/ws/install/mab_description/share/mab_description/meshes/hb40/rear.stl" scale="0.001 0.001 0.001"/>
      </geometry>
      <material name="silver"/>
    </visual>
    <collision>
      <origin rpy="0 0 0" xyz="-0.04 0.08 0"/>
      <geometry>
        <box size="0.2 0.05 0.1"/>
        <material name="invisible"/>
      </geometry>
    </collision>
  </link>
  <joint name="root" type="fixed">
    <parent link="base_link"/>
    <child link="body"/>
  </joint>
  <!-- Setup camera mount-->
  <!-- <xacro:realsense2_camera_mount parent="body"/> -->
  <!-- <xacro:realsense2_camera parent="body" name="d435i_camera"/> -->
  <link name="imu_link">
    <inertial>
      <origin rpy="0 0 0" xyz="0 0 0"/>
      <mass value="0.0"/>
      <inertia ixx="0" ixy="0" ixz="0" iyy="0" iyz="0" izz="0"/>
    </inertial>
    <visual>
      <origin rpy="0 0 0" xyz="0 0 0"/>
      <geometry>
        <box size="0.01 0.01 0.01"/>
      </geometry>
      <material name="red"/>
    </visual>
  </link>
  <joint name="imu_joint" type="fixed">
    <parent link="body"/>
    <child link="imu_link"/>
  </joint>
  <!-- LEG LINKS 0-4 -->
  <link name="fr_l0">
    <!-- <inertial>
      <origin rpy="0 0 0" xyz="0.0557 -0.016 0"/>
      <mass value="0.645"/>
      <inertia ixx="0.0052" ixy="0" ixz="0" iyy="0.0093" iyz="0" izz="0.0065"/>
    </inertial> -->
    <inertial>
      <origin xyz="50.33286050e-3 11.96674461e-3 0.45712186e-3"/>
      <mass value="0.64500000"/>
      <inertia ixx="498.32637726e-6" ixy="-43.44106123e-6" ixz="-0.22311702e-6" iyy="842.25430777e-6" iyz="-0.01118942e-6" izz="586.98453014e-6"/>
    </inertial>
    <visual>
      <origin rpy="0 0 0" xyz="0 0 0"/>
      <geometry>
        <mesh filename="file:///home/ws/install/mab_description/share/mab_description/meshes/hb40/l0r.stl" scale="0.001 0.001 0.001"/>
      </geometry>
      <material name="silver"/>
    </visual>
  </link>
  <link name="fr_l1">
    <!-- <inertial>
      <origin rpy="0 0 0" xyz="0.031 -0.016 0"/>
      <mass value="0.827"/>
      <inertia ixx="0.0330" ixy="0" ixz="0" iyy="0.0077" iyz="0" izz="0.0286"/>
    </inertial> -->
    <inertial>
      <origin xyz="41.97647538e-3 -50.28912232e-3 5.24458524e-3"/>
      <mass value="0.82700000"/>
      <inertia ixx="4027.34053636e-6" ixy="339.60345125e-6" ixz="-19.19423339e-6" iyy="719.63841788e-6" iyz="70.69913102e-6" izz="3870.59006761e-6"/>
    </inertial>
    <visual>
      <origin rpy="0 0 0" xyz="0 0 0"/>
      <geometry>
        <mesh filename="file:///home/ws/install/mab_description/share/mab_description/meshes/hb40/l1r.stl" scale="0.001 0.001 0.001"/>
      </geometry>
      <material name="orange"/>
    </visual>
    <collision>
      <origin rpy="0 1.57 0" xyz="0.0 0 0"/>
      <geometry>
        <cylinder length="0.08" radius="0.05"/>
      </geometry>
    </collision>
  </link>
  <link name="fr_l2">
    <!-- <inertial>
      <origin rpy="0 0 0" xyz="0.001 -0.104 -0.003"/>
      <mass value="0.118"/>
      <inertia ixx="0.0213" ixy="0" ixz="0" iyy="0.0002" iyz="0" izz="0.0212"/>
    </inertial> -->
    <inertial>
      <origin xyz="1.42261228e-3 -96.66711845e-3 1.53962525e-3"/>
      <mass value="0.11800000"/>
      <inertia ixx="524.76797677e-6" ixy="16.28790079e-6" ixz="0.26927944e-6" iyy="22.71638836e-6" iyz="-9.50678837e-6" izz="518.76368169e-6"/>
    </inertial>
    <visual>
      <origin rpy="0 0 0" xyz="0 0 0"/>
      <geometry>
        <mesh filename="file:///home/ws/install/mab_description/share/mab_description/meshes/hb40/l2r.stl" scale="0.001 0.001 0.001"/>
      </geometry>
      <material name="silver"/>
    </visual>
    <collision>
      <origin rpy="1.3 0 0" xyz="0 0.01 0.0055"/>
      <geometry>
        <cylinder length="0.0625" radius="0.01"/>
      </geometry>
      <material name="invisible"/>
    </collision>
    <collision>
      <origin rpy="1.67 0.0 0.05" xyz="0 -0.1 0.005"/>
      <geometry>
        <cylinder length="0.2" radius="0.015"/>
      </geometry>
      <material name="invisible"/>
    </collision>
  </link>
  <link name="fr_foot">
    <inertial>
      <origin rpy="0 0 0" xyz="0.0 0.0 0.0"/>
      <mass value="0.0"/>
      <inertia ixx="0.0" ixy="0" ixz="0" iyy="0.0" iyz="0" izz="0.0"/>
    </inertial>
    <visual>
      <origin rpy="0 0 0" xyz="0 0 0"/>
      <geometry>
        <sphere radius="0.021"/>
      </geometry>
      <material name="black"/>
    </visual>
    <collision>
      <origin rpy="0 0 0" xyz="0 0 0"/>
      <geometry>
        <sphere radius="0.02"/>
      </geometry>
    </collision>
  </link>
  <link name="fl_l0">
    <!-- <inertial>
      <origin rpy="0 0 0" xyz="0.0557 -0.016 0"/>
      <mass value="0.645"/>
      <inertia ixx="0.0052" ixy="0" ixz="0" iyy="0.0093" iyz="0" izz="0.0065"/>
    </inertial> -->
    <inertial>
      <origin xyz="50.33286050e-3 -11.96674465e-3 -0.45712069e-3"/>
      <mass value="0.64500000"/>
      <inertia ixx="498.32637694e-6" ixy="43.44106109e-6" ixz="0.22310959e-6" iyy="842.25430695e-6" iyz="-0.01120420e-6" izz="586.98452955e-6"/>
    </inertial>
    <visual>
      <origin rpy="0 0 0" xyz="0 0 0"/>
      <geometry>
        <mesh filename="file:///home/ws/install/mab_description/share/mab_description/meshes/hb40/l0l.stl" scale="0.001 0.001 0.001"/>
      </geometry>
      <material name="silver"/>
    </visual>
  </link>
  <link name="fl_l1">
    <!-- <inertial>
      <origin rpy="0 0 0" xyz="0.031 0.016 0"/>
      <mass value="0.827"/>
      <inertia ixx="0.0330" ixy="0" ixz="0" iyy="0.0077" iyz="0" izz="0.0286"/>
    </inertial> -->
    <inertial>
      <origin xyz="41.97647986e-3 50.28911905e-3 5.24459395e-3"/>
      <mass value="0.82700000"/>
      <inertia ixx="4027.34061087e-6" ixy="-339.60373031e-6" ixz="-19.19430819e-6" iyy="719.63850817e-6" iyz="-70.69968381e-6" izz="3870.59018254e-6"/>
    </inertial>
    <visual>
      <origin rpy="0 0 0" xyz="0 0 0"/>
      <geometry>
        <mesh filename="file:///home/ws/install/mab_description/share/mab_description/meshes/hb40/l1lf.stl" scale="0.001 0.001 0.001"/>
      </geometry>
      <material name="orange"/>
    </visual>
    <collision>
      <origin rpy="0 1.57 0" xyz="0.0 0 0"/>
      <geometry>
        <cylinder length="0.08" radius="0.05"/>
      </geometry>
    </collision>
  </link>
  <link name="fl_l2">
    <!-- <inertial>
      <origin rpy="0 0 0" xyz="0.001 0.104 -0.003"/>
      <mass value="0.118"/>
      <inertia ixx="0.0213" ixy="0" ixz="0" iyy="0.0002" iyz="0" izz="0.0212"/>
    </inertial> -->
    <inertial>
      <origin xyz="1.42261242e-3 96.66711821e-3 1.53963358e-3"/>
      <mass value="0.11800000"/>
      <inertia ixx="524.76797815e-6" ixy="-16.28789980e-6" ixz="0.26927746e-6" iyy="22.71638636e-6" iyz="9.50674532e-6" izz="518.76368492e-6"/>
    </inertial>
    <visual>
      <origin rpy="0 0 0" xyz="0 0 0"/>
      <geometry>
        <mesh filename="file:///home/ws/install/mab_description/share/mab_description/meshes/hb40/l2l.stl" scale="0.001 0.001 0.001"/>
      </geometry>
      <material name="silver"/>
    </visual>
    <collision>
      <origin rpy="-1.3 0.0 -0.00" xyz="0 -0.01 0.0055"/>
      <geometry>
        <cylinder length="0.0625" radius="0.01"/>
      </geometry>
      <material name="invisible"/>
    </collision>
    <collision>
      <origin rpy="-1.67 0.0 -0.05" xyz="0 0.1 0.005"/>
      <geometry>
        <cylinder length="0.2" radius="0.015"/>
      </geometry>
      <material name="invisible"/>
    </collision>
  </link>
  <link name="fl_foot">
    <inertial>
      <origin rpy="0 0 0" xyz="0.0 0.0 0.0"/>
      <mass value="0.0"/>
      <inertia ixx="0.0" ixy="0" ixz="0" iyy="0.0" iyz="0" izz="0.0"/>
    </inertial>
    <visual>
      <origin rpy="0 0 0" xyz="0 0 0"/>
      <geometry>
        <sphere radius="0.021"/>
      </geometry>
      <material name="black"/>
    </visual>
    <collision>
      <origin rpy="0 0 0" xyz="0 0 0"/>
      <geometry>
        <sphere radius="0.02"/>
      </geometry>
    </collision>
  </link>
  <link name="rl_l0">
    <!-- <inertial>
      <origin rpy="0 0 0" xyz="0.0557 -0.016 0"/>
      <mass value="0.645"/>
      <inertia ixx="0.0052" ixy="0" ixz="0" iyy="0.0093" iyz="0" izz="0.0065"/>
    </inertial> -->
    <inertial>
      <origin xyz="50.33286050e-3 -11.96674465e-3 -0.45712069e-3"/>
      <mass value="0.64500000"/>
      <inertia ixx="498.32637694e-6" ixy="43.44106109e-6" ixz="0.22310959e-6" iyy="842.25430695e-6" iyz="-0.01120420e-6" izz="586.98452955e-6"/>
    </inertial>
    <visual>
      <origin rpy="0 0 0" xyz="0 0 0"/>
      <geometry>
        <mesh filename="file:///home/ws/install/mab_description/share/mab_description/meshes/hb40/l0l.stl" scale="0.001 0.001 0.001"/>
      </geometry>
      <material name="silver"/>
    </visual>
  </link>
  <link name="rl_l1">
    <!-- <inertial>
      <origin rpy="0 0 0" xyz="0.031 0.016 0"/>
      <mass value="0.827"/>
      <inertia ixx="0.0330" ixy="0" ixz="0" iyy="0.0077" iyz="0" izz="0.0286"/>
    </inertial> -->
    <inertial>
      <origin xyz="41.97647986e-3 50.28911905e-3 5.24459395e-3"/>
      <mass value="0.82700000"/>
      <inertia ixx="4027.34061087e-6" ixy="-339.60373031e-6" ixz="-19.19430819e-6" iyy="719.63850817e-6" iyz="-70.69968381e-6" izz="3870.59018254e-6"/>
    </inertial>
    <visual>
      <origin rpy="0 0 0" xyz="0 0 0"/>
      <geometry>
        <mesh filename="file:///home/ws/install/mab_description/share/mab_description/meshes/hb40/l1lf.stl" scale="0.001 0.001 0.001"/>
      </geometry>
      <material name="orange"/>
    </visual>
    <collision>
      <origin rpy="0 1.57 0" xyz="0.0 0 0"/>
      <geometry>
        <cylinder length="0.08" radius="0.05"/>
      </geometry>
    </collision>
  </link>
  <link name="rl_l2">
    <!-- <inertial>
      <origin rpy="0 0 0" xyz="0.001 0.104 -0.003"/>
      <mass value="0.118"/>
      <inertia ixx="0.0213" ixy="0" ixz="0" iyy="0.0002" iyz="0" izz="0.0212"/>
    </inertial> -->
    <inertial>
      <origin xyz="1.42261242e-3 96.66711821e-3 1.53963358e-3"/>
      <mass value="0.11800000"/>
      <inertia ixx="524.76797815e-6" ixy="-16.28789980e-6" ixz="0.26927746e-6" iyy="22.71638636e-6" iyz="9.50674532e-6" izz="518.76368492e-6"/>
    </inertial>
    <visual>
      <origin rpy="0 0 0" xyz="0 0 0"/>
      <geometry>
        <mesh filename="file:///home/ws/install/mab_description/share/mab_description/meshes/hb40/l2l.stl" scale="0.001 0.001 0.001"/>
      </geometry>
      <material name="silver"/>
    </visual>
    <collision>
      <origin rpy="-1.3 0 0" xyz="0 -0.01 0.0055"/>
      <geometry>
        <cylinder length="0.0625" radius="0.01"/>
      </geometry>
      <material name="invisible"/>
    </collision>
    <collision>
      <origin rpy="-1.67 0.0 -0.05" xyz="0 0.1 0.005"/>
      <geometry>
        <cylinder length="0.2" radius="0.015"/>
        <material name="invisible"/>
      </geometry>
    </collision>
  </link>
  <link name="rl_foot">
    <inertial>
      <origin rpy="0 0 0" xyz="0.0 0.0 0.0"/>
      <mass value="0.0"/>
      <inertia ixx="0.0" ixy="0" ixz="0" iyy="0.0" iyz="0" izz="0.0"/>
    </inertial>
    <visual>
      <origin rpy="0 0 0" xyz="0 0 0"/>
      <geometry>
        <sphere radius="0.021"/>
      </geometry>
      <material name="black"/>
    </visual>
    <collision>
      <origin rpy="0 0 0" xyz="0 0 0"/>
      <geometry>
        <sphere radius="0.02"/>
      </geometry>
    </collision>
  </link>
  <link name="rr_l0">
    <!-- <inertial>
      <origin rpy="0 0 0" xyz="0.0557 -0.016 0"/>
      <mass value="0.645"/>
      <inertia ixx="0.0052" ixy="0" ixz="0" iyy="0.0093" iyz="0" izz="0.0065"/>
    </inertial> -->
    <inertial>
      <origin xyz="50.33286050e-3 11.96674461e-3 0.45712186e-3"/>
      <mass value="0.64500000"/>
      <inertia ixx="498.32637726e-6" ixy="-43.44106123e-6" ixz="-0.22311702e-6" iyy="842.25430777e-6" iyz="-0.01118942e-6" izz="586.98453014e-6"/>
    </inertial>
    <visual>
      <origin rpy="0 0 0" xyz="0 0 0"/>
      <geometry>
        <mesh filename="file:///home/ws/install/mab_description/share/mab_description/meshes/hb40/l0r.stl" scale="0.001 0.001 0.001"/>
      </geometry>
      <material name="silver"/>
    </visual>
  </link>
  <link name="rr_l1">
    <!-- <inertial>
      <origin rpy="0 0 0" xyz="0.031 -0.016 0"/>
      <mass value="0.827"/>
      <inertia ixx="0.0330" ixy="0" ixz="0" iyy="0.0077" iyz="0" izz="0.0286"/>
    </inertial> -->
    <inertial>
      <origin xyz="41.97647538e-3 -50.28912232e-3 5.24458524e-3"/>
      <mass value="0.82700000"/>
      <inertia ixx="4027.34053636e-6" ixy="339.60345125e-6" ixz="-19.19423339e-6" iyy="719.63841788e-6" iyz="70.69913102e-6" izz="3870.59006761e-6"/>
    </inertial>
    <visual>
      <origin rpy="0 0 0" xyz="0 0 0"/>
      <geometry>
        <mesh filename="file:///home/ws/install/mab_description/share/mab_description/meshes/hb40/l1r.stl" scale="0.001 0.001 0.001"/>
      </geometry>
      <material name="orange"/>
    </visual>
    <collision>
      <origin rpy="0 1.57 0" xyz="0.0 0 0"/>
      <geometry>
        <cylinder length="0.08" radius="0.05"/>
      </geometry>
    </collision>
  </link>
  <link name="rr_l2">
    <!-- <inertial>
      <origin rpy="0 0 0" xyz="0.001 -0.104 -0.003"/>
      <mass value="0.118"/>
      <inertia ixx="0.0213" ixy="0" ixz="0" iyy="0.0002" iyz="0" izz="0.0212"/>
    </inertial> -->
    <inertial>
      <origin xyz="1.42261228e-3 -96.66711845e-3 1.53962525e-3"/>
      <mass value="0.11800000"/>
      <inertia ixx="524.76797677e-6" ixy="16.28790079e-6" ixz="0.26927944e-6" iyy="22.71638836e-6" iyz="-9.50678837e-6" izz="518.76368169e-6"/>
    </inertial>
    <visual>
      <origin rpy="0 0 0" xyz="0 0 0"/>
      <geometry>
        <mesh filename="file:///home/ws/install/mab_description/share/mab_description/meshes/hb40/l2r.stl" scale="0.001 0.001 0.001"/>
      </geometry>
      <material name="silver"/>
    </visual>
    <collision>
      <origin rpy="1.3 0.0 0" xyz="0 0.01 0.0055"/>
      <geometry>
        <cylinder length="0.0625" radius="0.01"/>
        <material name="invisible"/>
      </geometry>
    </collision>
    <collision>
      <origin rpy="1.67 0.0 0.05" xyz="0 -0.1 0.005"/>
      <geometry>
        <cylinder length="0.2" radius="0.015"/>
        <material name="invisible"/>
      </geometry>
    </collision>
  </link>
  <link name="rr_foot">
    <inertial>
      <origin rpy="0 0 0" xyz="0.0 0.0 0.0"/>
      <mass value="0.0"/>
      <inertia ixx="0.0" ixy="0" ixz="0" iyy="0.0" iyz="0" izz="0.0"/>
    </inertial>
    <visual>
      <origin rpy="0 0 0" xyz="0 0 0"/>
      <geometry>
        <sphere radius="0.021"/>
      </geometry>
      <material name="black"/>
    </visual>
    <collision>
      <origin rpy="0 0 0" xyz="0 0 0"/>
      <geometry>
        <sphere radius="0.02"/>
      </geometry>
    </collision>
  </link>
  <!-- LEG JOINTS 0-4 -->
  <!-- Front Right Leg -->
  <joint armature="0.01" name="fr_j0" type="revolute">
    <parent link="body"/>
    <child link="fr_l0"/>
    <origin rpy="0 0 0" xyz="0.1375 -0.064 0"/>
    <axis xyz="1.0 0 0"/>
    <limit effort="16" lower="-1.57" upper="1.57" velocity="25"/>
  </joint>
  <joint name="fr_j1" type="revolute">
    <parent link="fr_l0"/>
    <child link="fr_l1"/>
    <origin rpy="0 0 -1.57" xyz="0.0555 -0.0125 0"/>
    <axis xyz="1.0 0 0"/>
    <limit effort="16" lower="-1.57" upper="1.57" velocity="25"/>
  </joint>
  <joint name="fr_j2" type="revolute">
    <parent link="fr_l1"/>
    <child link="fr_l2"/>
    <origin rpy="2.909 0 0" xyz="0.0584 -0.200 0"/>
    <axis xyz="1.0 0 0"/>
    <limit effort="16" lower="-2.53" upper="0.0" velocity="25"/>
  </joint>
  <joint name="fr_jFoot" type="fixed">
    <parent link="fr_l2"/>
    <child link="fr_foot"/>
    <origin rpy="0 0 0" xyz="0.0054 -0.200 0"/>
    <axis xyz="0.0 0 0"/>
  </joint>
  <!-- Front Left Leg -->
  <joint armature="0.01" name="fl_j0" type="revolute">
    <parent link="body"/>
    <child link="fl_l0"/>
    <origin rpy="0 0 0" xyz="0.1375 0.064 0"/>
    <axis xyz="1.0 0 0"/>
    <limit effort="16" lower="-1.57" upper="1.57" velocity="25"/>
  </joint>
  <joint name="fl_j1" type="revolute">
    <parent link="fl_l0"/>
    <child link="fl_l1"/>
    <origin rpy="0 0 1.57" xyz="0.0555 0.0125 0"/>
    <axis xyz="1.0 0 0"/>
    <limit effort="16" lower="-1.57" upper="1.57" velocity="25"/>
  </joint>
  <joint name="fl_j2" type="revolute">
    <parent link="fl_l1"/>
    <child link="fl_l2"/>
    <origin rpy="-2.909 0 0" xyz="0.0584 0.200 0"/>
    <axis xyz="1.0 0 0"/>
    <limit effort="16" lower="0.0" upper="2.53" velocity="25"/>
  </joint>
  <joint name="fl_jFoot" type="fixed">
    <parent link="fl_l2"/>
    <child link="fl_foot"/>
    <origin rpy="0 0 0" xyz="0.0054 0.200 0"/>
    <axis xyz="0.0 0 0"/>
  </joint>
  <!-- Rear Left Leg -->
  <joint armature="0.01" name="rl_j0" type="revolute">
    <parent link="rear"/>
    <child link="rl_l0"/>
    <origin rpy="0 0 1.57" xyz="-0.1025 0.10765 0"/>
    <axis xyz="1.0 0 0"/>
    <limit effort="16" lower="-1.57" upper="1.57" velocity="25"/>
  </joint>
  <joint name="rl_j1" type="revolute">
    <parent link="rl_l0"/>
    <child link="rl_l1"/>
    <origin rpy="3.14159 0 1.57" xyz="0.0555 0.0125 0"/>
    <axis xyz="1.0 0 0"/>
    <limit effort="16" lower="-1.57" upper="1.57" velocity="25"/>
  </joint>
  <joint name="rl_j2" type="revolute">
    <parent link="rl_l1"/>
    <child link="rl_l2"/>
    <origin rpy="-2.909 0 0" xyz="0.0584 0.20 0"/>
    <axis xyz="1.0 0 0"/>
    <limit effort="16" lower="0.0" upper="2.53" velocity="25"/>
  </joint>
  <joint name="rl_jFoot" type="fixed">
    <parent link="rl_l2"/>
    <child link="rl_foot"/>
    <origin rpy="0 0 0" xyz="0.0054 0.200 0"/>
    <axis xyz="0.0 0 0"/>
  </joint>
  <!-- Rear Right Leg -->
  <joint armature="0.01" name="rr_j0" type="revolute">
    <parent link="rear"/>
    <child link="rr_l0"/>
    <origin rpy="0 0 1.57" xyz="0.0255 0.10725 0"/>
    <axis xyz="1.0 0 0"/>
    <limit effort="16" lower="-1.57" upper="1.57" velocity="25"/>
  </joint>
  <joint name="rr_j1" type="revolute">
    <parent link="rr_l0"/>
    <child link="rr_l1"/>
    <origin rpy="3.14159 0 -1.57" xyz="0.0555 -0.0125 0"/>
    <axis xyz="1.0 0 0"/>
    <limit effort="16" lower="-1.57" upper="1.57" velocity="25"/>
  </joint>
  <joint name="rr_j2" type="revolute">
    <parent link="rr_l1"/>
    <child link="rr_l2"/>
    <origin rpy="2.909 0 0" xyz="0.0584 -0.20 0"/>
    <axis xyz="1.0 0 0"/>
    <limit effort="16" lower="-2.53" upper="0.0" velocity="25"/>
  </joint>
  <joint name="rr_jFoot" type="fixed">
    <parent link="rr_l2"/>
    <child link="rr_foot"/>
    <origin rpy="0 0 0" xyz="0.0054 -0.200 0"/>
    <axis xyz="0.0 0 0"/>
  </joint>
  <!-- Spine Joint-->
  <joint name="sp_j0" type="revolute">
    <parent link="body"/>
    <child link="rear"/>
    <origin rpy="3.14159 0 4.71" xyz="-0.141 -0.0395 0"/>
    <axis xyz="1 0 0"/>
    <limit effort="48.0" lower="-0.785" upper="0.785" velocity="3.15"/>
  </joint>
</robot>
